Workbook

Sheet Настройки
A1: УНИВЕРСАЛЬНЫЙ ГРАФИК ПЛАНИРОВАНИЯ ПРОИЗВОДСТВА — НАСТРОЙКИ
A3: Стартовая дата месяца: | C3: =DATE(2026,7,1) -> 46204
A4: Рабочих часов в смене: | C4: 8
A6: Код | B6: Название участка | C6: Сотрудников | D6: В бригаде | E6: Бригад/смену | F6: Часов в смене
A7: У1 | B7: Конструкторское бюро | C7: 4 | D7: 1 | E7: =ROUND(C7/D7,2) -> 4 | F7: =$C$4 -> 8
A8: У2 | B8: Снабжение | C8: 3 | D8: 1 | E8: =ROUND(C8/D8,2) -> 3 | F8: =$C$4 -> 8
A9: У3 | B9: Лазерная резка | C9: 4 | D9: 2 | E9: =ROUND(C9/D9,2) -> 2 | F9: =$C$4 -> 8
A10: У4 | B10: Гибка | C10: 4 | D10: 2 | E10: =ROUND(C10/D10,2) -> 2 | F10: =$C$4 -> 8
A11: У5 | B11: Механообработка | C11: 6 | D11: 2 | E11: =ROUND(C11/D11,2) -> 3 | F11: =$C$4 -> 8
A12: У6 | B12: Сварка | C12: 9 | D12: 2 | E12: =ROUND(C12/D12,2) -> 4.5 | F12: =$C$4 -> 8
A13: У7 | B13: Окраска | C13: 4 | D13: 2 | E13: =ROUND(C13/D13,2) -> 2 | F13: =$C$4 -> 8
A14: У8 | B14: Сборка | C14: 8 | D14: 2 | E14: =ROUND(C14/D14,2) -> 4 | F14: =$C$4 -> 8
A15: У9 | B15: Электромонтаж | C15: 10 | D15: 2 | E15: =ROUND(C15/D15,2) -> 5 | F15: =$C$4 -> 8
A16: У10 | B16: ОТК и склад ГП | C16: 3 | D16: 1 | E16: =ROUND(C16/D16,2) -> 3 | F16: =$C$4 -> 8
A19: Жёлтые ячейки — редактируемые. Название участка меняйте здесь — обновится везде.

Sheet Реестр заказов
A1: РЕЕСТР ЗАКАЗОВ (единый список для всех участков и мастер-графика)
A3: № | B3: Номер заказа | C3: Изделие | D3: Заказчик | E3: Дедлайн отгрузки | F3: Примечание
A4: 1 | B4: 26-1817 | C4: Шкаф РУНН | D4: НЛМК | E4: =DATE(2026,7,29) -> 46232
A5: 2 | B5: 26-1455 | C5: КТП-1000 | D5: ЛТК Свободный Сокол | E5: =DATE(2026,7,31) -> 46234
A6: 3 | B6: 26-1905 | C6: ЩО-70 | D6: Липецкцемент | E6: =DATE(2026,8,14) -> 46248
A7: 4
A8: 5
A9: 6
A10: 7
A11: 8
A12: 9
A13: 10
A14: 11
A15: 12
A16: 13
A17: 14
A18: 15
... A33: 30

Sheet Мастер
A1: МАСТЕР — СВОД ПО ВСЕМ УЧАСТКАМ: старт и завершение каждого заказа на каждом переделе
A2: № | B2: Заказ | C2: Изделие | D2: Дедлайн | E2: =Настройки!$B$7 -> Конструкторское бюро | G2: =Настройки!$B$8 -> Снабжение | I2: =Настройки!$B$9 -> Лазерная резка | K2: =Настройки!$B$10 -> Гибка | M2: =Настройки!$B$11 -> Механообработка | O2: =Настройки!$B$12 -> Сварка | Q2: =Настройки!$B$13 -> Окраска | S2: =Настройки!$B$14 -> Сборка | U2: =Настройки!$B$15 -> Электромонтаж | W2: =Настройки!$B$16 -> ОТК и склад ГП | Y2: Начало цикла | Z2: Завершение цикла | AA2: Цикл, дн.
E3: Старт | F3: Финиш | G3: Старт | H3: Финиш | I3: Старт | J3: Финиш | K3: Старт | L3: Финиш | M3: Старт | N3: Финиш | O3: Старт | P3: Финиш | Q3: Старт | R3: Финиш | S3: Старт | T3: Финиш | U3: Старт | V3: Финиш | W3: Старт | X3: Финиш
A4: 1 | B4: =IF('Реестр заказов'!B4="","",'Реестр заказов'!B4) -> 26-1817 | C4: =IF('Реестр заказов'!C4="","",'Реестр заказов'!C4) -> Шкаф РУНН | D4: =IF('Реестр заказов'!E4="","",'Реестр заказов'!E4) -> 46232 | E4: =IF($B4="","",IF(_xlfn.MINIFS('У1 Ввод'!$D$12:$D$251,'У1 Ввод'!$B$12:$B$251,$B4)=0,"",_xlfn.MINIFS('У1 Ввод'!$D$12:$D$251,'У1 Ввод'!$B$12:$B$251,$B4))) -> 46204 | F4: =IF($B4="","",IF(_xlfn.MAXIFS('У1 Ввод'!$F$12:$F$251,'У1 Ввод'!$B$12:$B$251,$B4)=0,"",_xlfn.MAXIFS('У1 Ввод'!$F$12:$F$251,'У1 Ввод'!$B$12:$B$251,$B4))) -> 46206 | G4: =IF($B4="","",IF(_xlfn.MINIFS('У2 Ввод'!$D$12:$D$251,'У2 Ввод'!$B$12:$B$251,$B4)=0,"",_xlfn.MINIFS('У2 Ввод'!$D$12:$D$251,'У2 Ввод'!$B$12:$B$251,$B4))) -> 46206 | H4: =IF($B4="","",IF(_xlfn.MAXIFS('У2 Ввод'!$F$12:$F$251,'У2 Ввод'!$B$12:$B$251,$B4)=0,"",_xlfn.MAXIFS('У2 Ввод'!$F$12:$F$251,'У2 Ввод'!$B$12:$B$251,$B4))) -> 46210 | I4: =IF($B4="","",IF(_xlfn.MINIFS('У3 Ввод'!$D$12:$D$251,'У3 Ввод'!$B$12:$B$251,$B4)=0,"",_xlfn.MINIFS('У3 Ввод'!$D$12:$D$251,'У3 Ввод'!$B$12:$B$251,$B4))) -> 46209 | J4: =IF($B4="","",IF(_xlfn.MAXIFS('У3 Ввод'!$F$12:$F$251,'У3 Ввод'!$B$12:$B$251,$B4)=0,"",_xlfn.MAXIFS('У3 Ввод'!$F$12:$F$251,'У3 Ввод'!$B$12:$B$251,$B4))) -> 46210 | K4: =IF($B4="","",IF(_xlfn.MINIFS('У4 Ввод'!$D$12:$D$251,'У4 Ввод'!$B$12:$B$251,$B4)=0,"",_xlfn.MINIFS('У4 Ввод'!$D$12:$D$251,'У4 Ввод'!$B$12:$B$251,$B4))) -> 46211 | L4: =IF($B4="","",IF(_xlfn.MAXIFS('У4 Ввод'!$F$12:$F$251,'У4 Ввод'!$B$12:$B$251,$B4)=0,"",_xlfn.MAXIFS('У4 Ввод'!$F$12:$F$251,'У4 Ввод'!$B$12:$B$251,$B4))) -> 46212 | M4: =IF($B4="","",IF(_xlfn.MINIFS('У5 Ввод'!$D$12:$D$251,'У5 Ввод'!$B$12:$B$251,$B4)=0,"",_xlfn.MINIFS('У5 Ввод'!$D$12:$D$251,'У5 Ввод'!$B$12:$B$251,$B4))) -> 46211 | N4: =IF($B4="","",IF(_xlfn.MAXIFS('У5 Ввод'!$F$12:$F$251,'У5 Ввод'!$B$12:$B$251,$B4)=0,"",_xlfn.MAXIFS('У5 Ввод'!$F$12:$F$251,'У5 Ввод'!$B$12:$B$251,$B4))) -> 46212 | O4: =IF($B4="","",IF(_xlfn.MINIFS('У6 Ввод'!$D$12:$D$251,'У6 Ввод'!$B$12:$B$251,$B4)=0,"",_xlfn.MINIFS('У6 Ввод'!$D$12:$D$251,'У6 Ввод'!$B$12:$B$251,$B4))) -> 46210 | P4: =IF($B4="","",IF(_xlfn.MAXIFS('У6 Ввод'!$F$12:$F$251,'У6 Ввод'!$B$12:$B$251,$B4)=0,"",_xlfn.MAXIFS('У6 Ввод'!$F$12:$F$251,'У6 Ввод'!$B$12:$B$251,$B4))) -> 46231 | Q4: =IF($B4="","",IF(_xlfn.MINIFS('У7 Ввод'!$D$12:$D$251,'У7 Ввод'!$B$12:$B$251,$B4)=0,"",_xlfn.MINIFS('У7 Ввод'!$D$12:$D$251,'У7 Ввод'!$B$12:$B$251,$B4))) -> 46218 | R4: =IF($B4="","",IF(_xlfn.MAXIFS('У7 Ввод'!$F$12:$F$251,'У7 Ввод'!$B$12:$B$251,$B4)=0,"",_xlfn.MAXIFS('У7 Ввод'!$F$12:$F$251,'У7 Ввод'!$B$12:$B$251,$B4))) -> 46219 | S4: =IF($B4="","",IF(_xlfn.MINIFS('У8 Ввод'!$D$12:$D$251,'У8 Ввод'!$B$12:$B$251,$B4)=0,"",_xlfn.MINIFS('У8 Ввод'!$D$12:$D$251,'У8 Ввод'!$B$12:$B$251,$B4))) -> 46220 | T4: =IF($B4="","",IF(_xlfn.MAXIFS('У8 Ввод'!$F$12:$F$251,'У8 Ввод'!$B$12:$B$251,$B4)=0,"",_xlfn.MAXIFS('У8 Ввод'!$F$12:$F$251,'У8 Ввод'!$B$12:$B$251,$B4))) -> 46224 | U4: =IF($B4="","",IF(_xlfn.MINIFS('У9 Ввод'!$D$12:$D$251,'У9 Ввод'!$B$12:$B$251,$B4)=0,"",_xlfn.MINIFS('У9 Ввод'!$D$12:$D$251,'У9 Ввод'!$B$12:$B$251,$B4))) -> 46225 | V4: =IF($B4="","",IF(_xlfn.MAXIFS('У9 Ввод'!$F$12:$F$251,'У9 Ввод'!$B$12:$B$251,$B4)=0,"",_xlfn.MAXIFS('У9 Ввод'!$F$12:$F$251,'У9 Ввод'!$B$12:$B$251,$B4))) -> 46227 | W4: =IF($B4="","",IF(_xlfn.MINIFS('У10 Ввод'!$D$12:$D$251,'У10 Ввод'!$B$12:$B$251,$B4)=0,"",_xlfn.MINIFS('У10 Ввод'!$D$12:$D$251,'У10 Ввод'!$B$12:$B$251,$B4))) -> 46230 | X4: =IF($B4="","",IF(_xlfn.MAXIFS('У10 Ввод'!$F$12:$F$251,'У10 Ввод'!$B$12:$B$251,$B4)=0,"",_xlfn.MAXIFS('У10 Ввод'!$F$12:$F$251,'У10 Ввод'!$B$12:$B$251,$B4))) -> 46231 | Y4: =IF(COUNT(E4,G4,I4,K4,M4,O4,Q4,S4,U4,W4)=0,"",MIN(E4,G4,I4,K4,M4,O4,Q4,S4,U4,W4)) -> 46204 | Z4: =IF(COUNT(F4,H4,J4,L4,N4,P4,R4,T4,V4,X4)=0,"",MAX(F4,H4,J4,L4,N4,P4,R4,T4,V4,X4)) -> 46231 | AA4: =IF(OR(Y4="",Z4=""),"",Z4-Y4+1) -> 28
A5: 2 | B5: =IF('Реестр заказов'!B5="","",'Реестр заказов'!B5) -> 26-1455 | C5: =IF('Реестр заказов'!C5="","",'Реестр заказов'!C5) -> КТП-1000 | D5: =IF('Реестр заказов'!E5="","",'Реестр заказов'!E5) -> 46234 | E5: =IF($B5="","",IF(_xlfn.MINIFS('У1 Ввод'!$D$12:$D$251,'У1 Ввод'!$B$12:$B$251,$B5)=0,"",_xlfn.MINIFS('У1 Ввод'!$D$12:$D$251,'У1 Ввод'!$B$12:$B$251,$B5))) -> 46205 | F5: =IF($B5="","",IF(_xlfn.MAXIFS('У1 Ввод'!$F$12:$F$251,'У1 Ввод'!$B$12:$B$251,$B5)=0,"",_xlfn.MAXIFS('У1 Ввод'!$F$12:$F$251,'У1 Ввод'!$B$12:$B$251,$B5))) -> 46209 | G5: =IF($B5="","",IF(_xlfn.MINIFS('У2 Ввод'!$D$12:$D$251,'У2 Ввод'!$B$12:$B$251,$B5)=0,"",_xlfn.MINIFS('У2 Ввод'!$D$12:$D$251,'У2 Ввод'!$B$12:$B$251,$B5))) -> 46209 | H5: =IF($B5="","",IF(_xlfn.MAXIFS('У2 Ввод'!$F$12:$F$251,'У2 Ввод'!$B$12:$B$251,$B5)=0,"",_xlfn.MAXIFS('У2 Ввод'!$F$12:$F$251,'У2 Ввод'!$B$12:$B$251,$B5))) -> 46210 | I5: =IF($B5="","",IF(_xlfn.MINIFS('У3 Ввод'!$D$12:$D$251,'У3 Ввод'!$B$12:$B$251,$B5)=0,"",_xlfn.MINIFS('У3 Ввод'!$D$12:$D$251,'У3 Ввод'!$B$12:$B$251,$B5))) -> 46210 | J5: =IF($B5="","",IF(_xlfn.MAXIFS('У3 Ввод'!$F$12:$F$251,'У3 Ввод'!$B$12:$B$251,$B5)=0,"",_xlfn.MAXIFS('У3 Ввод'!$F$12:$F$251,'У3 Ввод'!$B$12:$B$251,$B5))) -> 46211 | K5: =IF($B5="","",IF(_xlfn.MINIFS('У4 Ввод'!$D$12:$D$251,'У4 Ввод'!$B$12:$B$251,$B5)=0,"",_xlfn.MINIFS('У4 Ввод'!$D$12:$D$251,'У4 Ввод'!$B$12:$B$251,$B5))) -> 46212 | L5: =IF($B5="","",IF(_xlfn.MAXIFS('У4 Ввод'!$F$12:$F$251,'У4 Ввод'!$B$12:$B$251,$B5)=0,"",_xlfn.MAXIFS('У4 Ввод'!$F$12:$F$251,'У4 Ввод'!$B$12:$B$251,$B5))) -> 46213 | M5: =IF($B5="","",IF(_xlfn.MINIFS('У5 Ввод'!$D$12:$D$251,'У5 Ввод'!$B$12:$B$251,$B5)=0,"",_xlfn.MINIFS('У5 Ввод'!$D$12:$D$251,'У5 Ввод'!$B$12:$B$251,$B5))) | N5: =IF($B5="","",IF(_xlfn.MAXIFS('У5 Ввод'!$F$12:$F$251,'У5 Ввод'!$B$12:$B$251,$B5)=0,"",_xlfn.MAXIFS('У5 Ввод'!$F$12:$F$251,'У5 Ввод'!$B$12:$B$251,$B5))) | O5: =IF($B5="","",IF(_xlfn.MINIFS('У6 Ввод'!$D$12:$D$251,'У6 Ввод'!$B$12:$B$251,$B5)=0,"",_xlfn.MINIFS('У6 Ввод'!$D$12:$D$251,'У6 Ввод'!$B$12:$B$251,$B5))) -> 46210 | P5: =IF($B5="","",IF(_xlfn.MAXIFS('У6 Ввод'!$F$12:$F$251,'У6 Ввод'!$B$12:$B$251,$B5)=0,"",_xlfn.MAXIFS('У6 Ввод'!$F$12:$F$251,'У6 Ввод'!$B$12:$B$251,$B5))) -> 46231 | Q5: =IF($B5="","",IF(_xlfn.MINIFS('У7 Ввод'!$D$12:$D$251,'У7 Ввод'!$B$12:$B$251,$B5)=0,"",_xlfn.MINIFS('У7 Ввод'!$D$12:$D$251,'У7 Ввод'!$B$12:$B$251,$B5))) -> 46219 | R5: =IF($B5="","",IF(_xlfn.MAXIFS('У7 Ввод'!$F$12:$F$251,'У7 Ввод'!$B$12:$B$251,$B5)=0,"",_xlfn.MAXIFS('У7 Ввод'!$F$12:$F$251,'У7 Ввод'!$B$12:$B$251,$B5))) -> 46220 | S5: =IF($B5="","",IF(_xlfn.MINIFS('У8 Ввод'!$D$12:$D$251,'У8 Ввод'!$B$12:$B$251,$B5)=0,"",_xlfn.MINIFS('У8 Ввод'!$D$12:$D$251,'У8 Ввод'!$B$12:$B$251,$B5))) -> 46223 | T5: =IF($B5="","",IF(_xlfn.MAXIFS('У8 Ввод'!$F$12:$F$251,'У8 Ввод'!$B$12:$B$251,$B5)=0,"",_xlfn.MAXIFS('У8 Ввод'!$F$12:$F$251,'У8 Ввод'!$B$12:$B$251,$B5))) -> 46225 | U5: =IF($B5="","",IF(_xlfn.MINIFS('У9 Ввод'!$D$12:$D$251,'У9 Ввод'!$B$12:$B$251,$B5)=0,"",_xlfn.MINIFS('У9 Ввод'!$D$12:$D$251,'У9 Ввод'!$B$12:$B$251,$B5))) -> 46226 | V5: =IF($B5="","",IF(_xlfn.MAXIFS('У9 Ввод'!$F$12:$F$251,'У9 Ввод'!$B$12:$B$251,$B5)=0,"",_xlfn.MAXIFS('У9 Ввод'!$F$12:$F$251,'У9 Ввод'!$B$12:$B$251,$B5))) -> 46230 | W5: =IF($B5="","",IF(_xlfn.MINIFS('У10 Ввод'!$D$12:$D$251,'У10 Ввод'!$B$12:$B$251,$B5)=0,"",_xlfn.MINIFS('У10 Ввод'!$D$12:$D$251,'У10 Ввод'!$B$12:$B$251,$B5))) -> 46232 | X5: =IF($B5="","",IF(_xlfn.MAXIFS('У10 Ввод'!$F$12:$F$251,'У10 Ввод'!$B$12:$B$251,$B5)=0,"",_xlfn.MAXIFS('У10 Ввод'!$F$12:$F$251,'У10 Ввод'!$B$12:$B$251,$B5))) -> 46233 | Y5: =IF(COUNT(E5,G5,I5,K5,M5,O5,Q5,S5,U5,W5)=0,"",MIN(E5,G5,I5,K5,M5,O5,Q5,S5,U5,W5)) -> 46205 | Z5: =IF(COUNT(F5,H5,J5,L5,N5,P5,R5,T5,V5,X5)=0,"",MAX(F5,H5,J5,L5,N5,P5,R5,T5,V5,X5)) -> 46233 | AA5: =IF(OR(Y5="",Z5=""),"",Z5-Y5+1) -> 29
A6: 3 | B6: =IF('Реестр заказов'!B6="","",'Реестр заказов'!B6) -> 26-1905 | C6: =IF('Реестр заказов'!C6="","",'Реестр заказов'!C6) -> ЩО-70 | D6: =IF('Реестр заказов'!E6="","",'Реестр заказов'!E6) -> 46248 | E6: =IF($B6="","",IF(_xlfn.MINIFS('У1 Ввод'!$D$12:$D$251,'У1 Ввод'!$B$12:$B$251,$B6)=0,"",_xlfn.MINIFS('У1 Ввод'!$D$12:$D$251,'У1 Ввод'!$B$12:$B$251,$B6))) -> 46209 | F6: =IF($B6="","",IF(_xlfn.MAXIFS('У1 Ввод'!$F$12:$F$251,'У1 Ввод'!$B$12:$B$251,$B6)=0,"",_xlfn.MAXIFS('У1 Ввод'!$F$12:$F$251,'У1 Ввод'!$B$12:$B$251,$B6))) -> 46213 | G6: =IF($B6="","",IF(_xlfn.MINIFS('У2 Ввод'!$D$12:$D$251,'У2 Ввод'!$B$12:$B$251,$B6)=0,"",_xlfn.MINIFS('У2 Ввод'!$D$12:$D$251,'У2 Ввод'!$B$12:$B$251,$B6))) | H6: =IF($B6="","",IF(_xlfn.MAXIFS('У2 Ввод'!$F$12:$F$251,'У2 Ввод'!$B$12:$B$251,$B6)=0,"",_xlfn.MAXIFS('У2 Ввод'!$F$12:$F$251,'У2 Ввод'!$B$12:$B$251,$B6))) | I6: =IF($B6="","",IF(_xlfn.MINIFS('У3 Ввод'!$D$12:$D$251,'У3 Ввод'!$B$12:$B$251,$B6)=0,"",_xlfn.MINIFS('У3 Ввод'!$D$12:$D$251,'У3 Ввод'!$B$12:$B$251,$B6))) -> 46216 | J6: =IF($B6="","",IF(_xlfn.MAXIFS('У3 Ввод'!$F$12:$F$251,'У3 Ввод'!$B$12:$B$251,$B6)=0,"",_xlfn.MAXIFS('У3 Ввод'!$F$12:$F$251,'У3 Ввод'!$B$12:$B$251,$B6))) -> 46217 | K6: =IF($B6="","",IF(_xlfn.MINIFS('У4 Ввод'!$D$12:$D$251,'У4 Ввод'!$B$12:$B$251,$B6)=0,"",_xlfn.MINIFS('У4 Ввод'!$D$12:$D$251,'У4 Ввод'!$B$12:$B$251,$B6))) | L6: =IF($B6="","",IF(_xlfn.MAXIFS('У4 Ввод'!$F$12:$F$251,'У4 Ввод'!$B$12:$B$251,$B6)=0,"",_xlfn.MAXIFS('У4 Ввод'!$F$12:$F$251,'У4 Ввод'!$B$12:$B$251,$B6))) | M6: =IF($B6="","",IF(_xlfn.MINIFS('У5 Ввод'!$D$12:$D$251,'У5 Ввод'!$B$12:$B$251,$B6)=0,"",_xlfn.MINIFS('У5 Ввод'!$D$12:$D$251,'У5 Ввод'!$B$12:$B$251,$B6))) | N6: =IF($B6="","",IF(_xlfn.MAXIFS('У5 Ввод'!$F$12:$F$251,'У5 Ввод'!$B$12:$B$251,$B6)=0,"",_xlfn.MAXIFS('У5 Ввод'!$F$12:$F$251,'У5 Ввод'!$B$12:$B$251,$B6))) | O6: =IF($B6="","",IF(_xlfn.MINIFS('У6 Ввод'!$D$12:$D$251,'У6 Ввод'!$B$12:$B$251,$B6)=0,"",_xlfn.MINIFS('У6 Ввод'!$D$12:$D$251,'У6 Ввод'!$B$12:$B$251,$B6))) -> 46223 | P6: =IF($B6="","",IF(_xlfn.MAXIFS('У6 Ввод'!$F$12:$F$251,'У6 Ввод'!$B$12:$B$251,$B6)=0,"",_xlfn.MAXIFS('У6 Ввод'!$F$12:$F$251,'У6 Ввод'!$B$12:$B$251,$B6))) -> 46225 | Q6: =IF($B6="","",IF(_xlfn.MINIFS('У7 Ввод'!$D$12:$D$251,'У7 Ввод'!$B$12:$B$251,$B6)=0,"",_xlfn.MINIFS('У7 Ввод'!$D$12:$D$251,'У7 Ввод'!$B$12:$B$251,$B6))) | R6: =IF($B6="","",IF(_xlfn.MAXIFS('У7 Ввод'!$F$12:$F$251,'У7 Ввод'!$B$12:$B$251,$B6)=0,"",_xlfn.MAXIFS('У7 Ввод'!$F$12:$F$251,'У7 Ввод'!$B$12:$B$251,$B6))) | S6: =IF($B6="","",IF(_xlfn.MINIFS('У8 Ввод'!$D$12:$D$251,'У8 Ввод'!$B$12:$B$251,$B6)=0,"",_xlfn.MINIFS('У8 Ввод'!$D$12:$D$251,'У8 Ввод'!$B$12:$B$251,$B6))) | T6: =IF($B6="","",IF(_xlfn.MAXIFS('У8 Ввод'!$F$12:$F$251,'У8 Ввод'!$B$12:$B$251,$B6)=0,"",_xlfn.MAXIFS('У8 Ввод'!$F$12:$F$251,'У8 Ввод'!$B$12:$B$251,$B6))) | U6: =IF($B6="","",IF(_xlfn.MINIFS('У9 Ввод'!$D$12:$D$251,'У9 Ввод'!$B$12:$B$251,$B6)=0,"",_xlfn.MINIFS('У9 Ввод'!$D$12:$D$251,'У9 Ввод'!$B$12:$B$251,$B6))) | V6: =IF($B6="","",IF(_xlfn.MAXIFS('У9 Ввод'!$F$12:$F$251,'У9 Ввод'!$B$12:$B$251,$B6)=0,"",_xlfn.MAXIFS('У9 Ввод'!$F$12:$F$251,'У9 Ввод'!$B$12:$B$251,$B6))) | W6: =IF($B6="","",IF(_xlfn.MINIFS('У10 Ввод'!$D$12:$D$251,'У10 Ввод'!$B$12:$B$251,$B6)=0,"",_xlfn.MINIFS('У10 Ввод'!$D$12:$D$251,'У10 Ввод'!$B$12:$B$251,$B6))) -> 46233 | X6: =IF($B6="","",IF(_xlfn.MAXIFS('У10 Ввод'!$F$12:$F$251,'У10 Ввод'!$B$12:$B$251,$B6)=0,"",_xlfn.MAXIFS('У10 Ввод'!$F$12:$F$251,'У10 Ввод'!$B$12:$B$251,$B6))) -> 46233 | Y6: =IF(COUNT(E6,G6,I6,K6,M6,O6,Q6,S6,U6,W6)=0,"",MIN(E6,G6,I6,K6,M6,O6,Q6,S6,U6,W6)) -> 46209 | Z6: =IF(COUNT(F6,H6,J6,L6,N6,P6,R6,T6,V6,X6)=0,"",MAX(F6,H6,J6,L6,N6,P6,R6,T6,V6,X6)) -> 46233 | AA6: =IF(OR(Y6="",Z6=""),"",Z6-Y6+1) -> 25
A7: 4 | B7: =IF('Реестр заказов'!B7="","",'Реестр заказов'!B7) | C7: =IF('Реестр заказов'!C7="","",'Реестр заказов'!C7) | D7: =IF('Реестр заказов'!E7="","",'Реестр заказов'!E7) | E7: =IF($B7="","",IF(_xlfn.MINIFS('У1 Ввод'!$D$12:$D$251,'У1 Ввод'!$B$12:$B$251,$B7)=0,"",_xlfn.MINIFS('У1 Ввод'!$D$12:$D$251,'У1 Ввод'!$B$12:$B$251,$B7))) | F7: =IF($B7="","",IF(_xlfn.MAXIFS('У1 Ввод'!$F$12:$F$251,'У1 Ввод'!$B$12:$B$251,$B7)=0,"",_xlfn.MAXIFS('У1 Ввод'!$F$12:$F$251,'У1 Ввод'!$B$12:$B$251,$B7))) | G7: =IF($B7="","",IF(_xlfn.MINIFS('У2 Ввод'!$D$12:$D$251,'У2 Ввод'!$B$12:$B$251,$B7)=0,"",_xlfn.MINIFS('У2 Ввод'!$D$12:$D$251,'У2 Ввод'!$B$12:$B$251,$B7))) | H7: =IF($B7="","",IF(_xlfn.MAXIFS('У2 Ввод'!$F$12:$F$251,'У2 Ввод'!$B$12:$B$251,$B7)=0,"",_xlfn.MAXIFS('У2 Ввод'!$F$12:$F$251,'У2 Ввод'!$B$12:$B$251,$B7))) | I7: =IF($B7="","",IF(_xlfn.MINIFS('У3 Ввод'!$D$12:$D$251,'У3 Ввод'!$B$12:$B$251,$B7)=0,"",_xlfn.MINIFS('У3 Ввод'!$D$12:$D$251,'У3 Ввод'!$B$12:$B$251,$B7))) | J7: =IF($B7="","",IF(_xlfn.MAXIFS('У3 Ввод'!$F$12:$F$251,'У3 Ввод'!$B$12:$B$251,$B7)=0,"",_xlfn.MAXIFS('У3 Ввод'!$F$12:$F$251,'У3 Ввод'!$B$12:$B$251,$B7))) | K7: =IF($B7="","",IF(_xlfn.MINIFS('У4 Ввод'!$D$12:$D$251,'У4 Ввод'!$B$12:$B$251,$B7)=0,"",_xlfn.MINIFS('У4 Ввод'!$D$12:$D$251,'У4 Ввод'!$B$12:$B$251,$B7))) | L7: =IF($B7="","",IF(_xlfn.MAXIFS('У4 Ввод'!$F$12:$F$251,'У4 Ввод'!$B$12:$B$251,$B7)=0,"",_xlfn.MAXIFS('У4 Ввод'!$F$12:$F$251,'У4 Ввод'!$B$12:$B$251,$B7))) | M7: =IF($B7="","",IF(_xlfn.MINIFS('У5 Ввод'!$D$12:$D$251,'У5 Ввод'!$B$12:$B$251,$B7)=0,"",_xlfn.MINIFS('У5 Ввод'!$D$12:$D$251,'У5 Ввод'!$B$12:$B$251,$B7))) | N7: =IF($B7="","",IF(_xlfn.MAXIFS('У5 Ввод'!$F$12:$F$251,'У5 Ввод'!$B$12:$B$251,$B7)=0,"",_xlfn.MAXIFS('У5 Ввод'!$F$12:$F$251,'У5 Ввод'!$B$12:$B$251,$B7))) | O7: =IF($B7="","",IF(_xlfn.MINIFS('У6 Ввод'!$D$12:$D$251,'У6 Ввод'!$B$12:$B$251,$B7)=0,"",_xlfn.MINIFS('У6 Ввод'!$D$12:$D$251,'У6 Ввод'!$B$12:$B$251,$B7))) | P7: =IF($B7="","",IF(_xlfn.MAXIFS('У6 Ввод'!$F$12:$F$251,'У6 Ввод'!$B$12:$B$251,$B7)=0,"",_xlfn.MAXIFS('У6 Ввод'!$F$12:$F$251,'У6 Ввод'!$B$12:$B$251,$B7))) | Q7: =IF($B7="","",IF(_xlfn.MINIFS('У7 Ввод'!$D$12:$D$251,'У7 Ввод'!$B$12:$B$251,$B7)=0,"",_xlfn.MINIFS('У7 Ввод'!$D$12:$D$251,'У7 Ввод'!$B$12:$B$251,$B7))) | R7: =IF($B7="","",IF(_xlfn.MAXIFS('У7 Ввод'!$F$12:$F$251,'У7 Ввод'!$B$12:$B$251,$B7)=0,"",_xlfn.MAXIFS('У7 Ввод'!$F$12:$F$251,'У7 Ввод'!$B$12:$B$251,$B7))) | S7: =IF($B7="","",IF(_xlfn.MINIFS('У8 Ввод'!$D$12:$D$251,'У8 Ввод'!$B$12:$B$251,$B7)=0,"",_xlfn.MINIFS('У8 Ввод'!$D$12:$D$251,'У8 Ввод'!$B$12:$B$251,$B7))) | T7: =IF($B7="","",IF(_xlfn.MAXIFS('У8 Ввод'!$F$12:$F$251,'У8 Ввод'!$B$12:$B$251,$B7)=0,"",_xlfn.MAXIFS('У8 Ввод'!$F$12:$F$251,'У8 Ввод'!$B$12:$B$251,$B7))) | U7: =IF($B7="","",IF(_xlfn.MINIFS('У9 Ввод'!$D$12:$D$251,'У9 Ввод'!$B$12:$B$251,$B7)=0,"",_xlfn.MINIFS('У9 Ввод'!$D$12:$D$251,'У9 Ввод'!$B$12:$B$251,$B7))) | V7: =IF($B7="","",IF(_xlfn.MAXIFS('У9 Ввод'!$F$12:$F$251,'У9 Ввод'!$B$12:$B$251,$B7)=0,"",_xlfn.MAXIFS('У9 Ввод'!$F$12:$F$251,'У9 Ввод'!$B$12:$B$251,$B7))) | W7: =IF($B7="","",IF(_xlfn.MINIFS('У10 Ввод'!$D$12:$D$251,'У10 Ввод'!$B$12:$B$251,$B7)=0,"",_xlfn.MINIFS('У10 Ввод'!$D$12:$D$251,'У10 Ввод'!$B$12:$B$251,$B7))) | X7: =IF($B7="","",IF(_xlfn.MAXIFS('У10 Ввод'!$F$12:$F$251,'У10 Ввод'!$B$12:$B$251,$B7)=0,"",_xlfn.MAXIFS('У10 Ввод'!$F$12:$F$251,'У10 Ввод'!$B$12:$B$251,$B7))) | Y7: =IF(COUNT(E7,G7,I7,K7,M7,O7,Q7,S7,U7,W7)=0,"",MIN(E7,G7,I7,K7,M7,O7,Q7,S7,U7,W7)) | Z7: =IF(COUNT(F7,H7,J7,L7,N7,P7,R7,T7,V7,X7)=0,"",MAX(F7,H7,J7,L7,N7,P7,R7,T7,V7,X7)) | AA7: =IF(OR(Y7="",Z7=""),"",Z7-Y7+1)
A8: 5 | B8: =IF('Реестр заказов'!B8="","",'Реестр заказов'!B8) | C8: =IF('Реестр заказов'!C8="","",'Реестр заказов'!C8) | D8: =IF('Реестр заказов'!E8="","",'Реестр заказов'!E8) | E8: =IF($B8="","",IF(_xlfn.MINIFS('У1 Ввод'!$D$12:$D$251,'У1 Ввод'!$B$12:$B$251,$B8)=0,"",_xlfn.MINIFS('У1 Ввод'!$D$12:$D$251,'У1 Ввод'!$B$12:$B$251,$B8))) | F8: =IF($B8="","",IF(_xlfn.MAXIFS('У1 Ввод'!$F$12:$F$251,'У1 Ввод'!$B$12:$B$251,$B8)=0,"",_xlfn.MAXIFS('У1 Ввод'!$F$12:$F$251,'У1 Ввод'!$B$12:$B$251,$B8))) | G8: =IF($B8="","",IF(_xlfn.MINIFS('У2 Ввод'!$D$12:$D$251,'У2 Ввод'!$B$12:$B$251,$B8)=0,"",_xlfn.MINIFS('У2 Ввод'!$D$12:$D$251,'У2 Ввод'!$B$12:$B$251,$B8))) | H8: =IF($B8="","",IF(_xlfn.MAXIFS('У2 Ввод'!$F$12:$F$251,'У2 Ввод'!$B$12:$B$251,$B8)=0,"",_xlfn.MAXIFS('У2 Ввод'!$F$12:$F$251,'У2 Ввод'!$B$12:$B$251,$B8))) | I8: =IF($B8="","",IF(_xlfn.MINIFS('У3 Ввод'!$D$12:$D$251,'У3 Ввод'!$B$12:$B$251,$B8)=0,"",_xlfn.MINIFS('У3 Ввод'!$D$12:$D$251,'У3 Ввод'!$B$12:$B$251,$B8))) | J8: =IF($B8="","",IF(_xlfn.MAXIFS('У3 Ввод'!$F$12:$F$251,'У3 Ввод'!$B$12:$B$251,$B8)=0,"",_xlfn.MAXIFS('У3 Ввод'!$F$12:$F$251,'У3 Ввод'!$B$12:$B$251,$B8))) | K8: =IF($B8="","",IF(_xlfn.MINIFS('У4 Ввод'!$D$12:$D$251,'У4 Ввод'!$B$12:$B$251,$B8)=0,"",_xlfn.MINIFS('У4 Ввод'!$D$12:$D$251,'У4 Ввод'!$B$12:$B$251,$B8))) | L8: =IF($B8="","",IF(_xlfn.MAXIFS('У4 Ввод'!$F$12:$F$251,'У4 Ввод'!$B$12:$B$251,$B8)=0,"",_xlfn.MAXIFS('У4 Ввод'!$F$12:$F$251,'У4 Ввод'!$B$12:$B$251,$B8))) | M8: =IF($B8="","",IF(_xlfn.MINIFS('У5 Ввод'!$D$12:$D$251,'У5 Ввод'!$B$12:$B$251,$B8)=0,"",_xlfn.MINIFS('У5 Ввод'!$D$12:$D$251,'У5 Ввод'!$B$12:$B$251,$B8))) | N8: =IF($B8="","",IF(_xlfn.MAXIFS('У5 Ввод'!$F$12:$F$251,'У5 Ввод'!$B$12:$B$251,$B8)=0,"",_xlfn.MAXIFS('У5 Ввод'!$F$12:$F$251,'У5 Ввод'!$B$12:$B$251,$B8))) | O8: =IF($B8="","",IF(_xlfn.MINIFS('У6 Ввод'!$D$12:$D$251,'У6 Ввод'!$B$12:$B$251,$B8)=0,"",_xlfn.MINIFS('У6 Ввод'!$D$12:$D$251,'У6 Ввод'!$B$12:$B$251,$B8))) | P8: =IF($B8="","",IF(_xlfn.MAXIFS('У6 Ввод'!$F$12:$F$251,'У6 Ввод'!$B$12:$B$251,$B8)=0,"",_xlfn.MAXIFS('У6 Ввод'!$F$12:$F$251,'У6 Ввод'!$B$12:$B$251,$B8))) | Q8: =IF($B8="","",IF(_xlfn.MINIFS('У7 Ввод'!$D$12:$D$251,'У7 Ввод'!$B$12:$B$251,$B8)=0,"",_xlfn.MINIFS('У7 Ввод'!$D$12:$D$251,'У7 Ввод'!$B$12:$B$251,$B8))) | R8: =IF($B8="","",IF(_xlfn.MAXIFS('У7 Ввод'!$F$12:$F$251,'У7 Ввод'!$B$12:$B$251,$B8)=0,"",_xlfn.MAXIFS('У7 Ввод'!$F$12:$F$251,'У7 Ввод'!$B$12:$B$251,$B8))) | S8: =IF($B8="","",IF(_xlfn.MINIFS('У8 Ввод'!$D$12:$D$251,'У8 Ввод'!$B$12:$B$251,$B8)=0,"",_xlfn.MINIFS('У8 Ввод'!$D$12:$D$251,'У8 Ввод'!$B$12:$B$251,$B8))) | T8: =IF($B8="","",IF(_xlfn.MAXIFS('У8 Ввод'!$F$12:$F$251,'У8 Ввод'!$B$12:$B$251,$B8)=0,"",_xlfn.MAXIFS('У8 Ввод'!$F$12:$F$251,'У8 Ввод'!$B$12:$B$251,$B8))) | U8: =IF($B8="","",IF(_xlfn.MINIFS('У9 Ввод'!$D$12:$D$251,'У9 Ввод'!$B$12:$B$251,$B8)=0,"",_xlfn.MINIFS('У9 Ввод'!$D$12:$D$251,'У9 Ввод'!$B$12:$B$251,$B8))) | V8: =IF($B8="","",IF(_xlfn.MAXIFS('У9 Ввод'!$F$12:$F$251,'У9 Ввод'!$B$12:$B$251,$B8)=0,"",_xlfn.MAXIFS('У9 Ввод'!$F$12:$F$251,'У9 Ввод'!$B$12:$B$251,$B8))) | W8: =IF($B8="","",IF(_xlfn.MINIFS('У10 Ввод'!$D$12:$D$251,'У10 Ввод'!$B$12:$B$251,$B8)=0,"",_xlfn.MINIFS('У10 Ввод'!$D$12:$D$251,'У10 Ввод'!$B$12:$B$251,$B8))) | X8: =IF($B8="","",IF(_xlfn.MAXIFS('У10 Ввод'!$F$12:$F$251,'У10 Ввод'!$B$12:$B$251,$B8)=0,"",_xlfn.MAXIFS('У10 Ввод'!$F$12:$F$251,'У10 Ввод'!$B$12:$B$251,$B8))) | Y8: =IF(COUNT(E8,G8,I8,K8,M8,O8,Q8,S8,U8,W8)=0,"",MIN(E8,G8,I8,K8,M8,O8,Q8,S8,U8,W8)) | Z8: =IF(COUNT(F8,H8,J8,L8,N8,P8,R8,T8,V8,X8)=0,"",MAX(F8,H8,J8,L8,N8,P8,R8,T8,V8,X8)) | AA8: =IF(OR(Y8="",Z8=""),"",Z8-Y8+1)
A9: 6 | B9: =IF('Реестр заказов'!B9="","",'Реестр заказов'!B9) | C9: =IF('Реестр заказов'!C9="","",'Реестр заказов'!C9) | D9: =IF('Реестр заказов'!E9="","",'Реестр заказов'!E9) | E9: =IF($B9="","",IF(_xlfn.MINIFS('У1 Ввод'!$D$12:$D$251,'У1 Ввод'!$B$12:$B$251,$B9)=0,"",_xlfn.MINIFS('У1 Ввод'!$D$12:$D$251,'У1 Ввод'!$B$12:$B$251,$B9))) | F9: =IF($B9="","",IF(_xlfn.MAXIFS('У1 Ввод'!$F$12:$F$251,'У1 Ввод'!$B$12:$B$251,$B9)=0,"",_xlfn.MAXIFS('У1 Ввод'!$F$12:$F$251,'У1 Ввод'!$B$12:$B$251,$B9))) | G9: =IF($B9="","",IF(_xlfn.MINIFS('У2 Ввод'!$D$12:$D$251,'У2 Ввод'!$B$12:$B$251,$B9)=0,"",_xlfn.MINIFS('У2 Ввод'!$D$12:$D$251,'У2 Ввод'!$B$12:$B$251,$B9))) | H9: =IF($B9="","",IF(_xlfn.MAXIFS('У2 Ввод'!$F$12:$F$251,'У2 Ввод'!$B$12:$B$251,$B9)=0,"",_xlfn.MAXIFS('У2 Ввод'!$F$12:$F$251,'У2 Ввод'!$B$12:$B$251,$B9))) | I9: =IF($B9="","",IF(_xlfn.MINIFS('У3 Ввод'!$D$12:$D$251,'У3 Ввод'!$B$12:$B$251,$B9)=0,"",_xlfn.MINIFS('У3 Ввод'!$D$12:$D$251,'У3 Ввод'!$B$12:$B$251,$B9))) | J9: =IF($B9="","",IF(_xlfn.MAXIFS('У3 Ввод'!$F$12:$F$251,'У3 Ввод'!$B$12:$B$251,$B9)=0,"",_xlfn.MAXIFS('У3 Ввод'!$F$12:$F$251,'У3 Ввод'!$B$12:$B$251,$B9))) | K9: =IF($B9="","",IF(_xlfn.MINIFS('У4 Ввод'!$D$12:$D$251,'У4 Ввод'!$B$12:$B$251,$B9)=0,"",_xlfn.MINIFS('У4 Ввод'!$D$12:$D$251,'У4 Ввод'!$B$12:$B$251,$B9))) | L9: =IF($B9="","",IF(_xlfn.MAXIFS('У4 Ввод'!$F$12:$F$251,'У4 Ввод'!$B$12:$B$251,$B9)=0,"",_xlfn.MAXIFS('У4 Ввод'!$F$12:$F$251,'У4 Ввод'!$B$12:$B$251,$B9))) | M9: =IF($B9="","",IF(_xlfn.MINIFS('У5 Ввод'!$D$12:$D$251,'У5 Ввод'!$B$12:$B$251,$B9)=0,"",_xlfn.MINIFS('У5 Ввод'!$D$12:$D$251,'У5 Ввод'!$B$12:$B$251,$B9))) | N9: =IF($B9="","",IF(_xlfn.MAXIFS('У5 Ввод'!$F$12:$F$251,'У5 Ввод'!$B$12:$B$251,$B9)=0,"",_xlfn.MAXIFS('У5 Ввод'!$F$12:$F$251,'У5 Ввод'!$B$12:$B$251,$B9))) | O9: =IF($B9="","",IF(_xlfn.MINIFS('У6 Ввод'!$D$12:$D$251,'У6 Ввод'!$B$12:$B$251,$B9)=0,"",_xlfn.MINIFS('У6 Ввод'!$D$12:$D$251,'У6 Ввод'!$B$12:$B$251,$B9))) | P9: =IF($B9="","",IF(_xlfn.MAXIFS('У6 Ввод'!$F$12:$F$251,'У6 Ввод'!$B$12:$B$251,$B9)=0,"",_xlfn.MAXIFS('У6 Ввод'!$F$12:$F$251,'У6 Ввод'!$B$12:$B$251,$B9))) | Q9: =IF($B9="","",IF(_xlfn.MINIFS('У7 Ввод'!$D$12:$D$251,'У7 Ввод'!$B$12:$B$251,$B9)=0,"",_xlfn.MINIFS('У7 Ввод'!$D$12:$D$251,'У7 Ввод'!$B$12:$B$251,$B9))) | R9: =IF($B9="","",IF(_xlfn.MAXIFS('У7 Ввод'!$F$12:$F$251,'У7 Ввод'!$B$12:$B$251,$B9)=0,"",_xlfn.MAXIFS('У7 Ввод'!$F$12:$F$251,'У7 Ввод'!$B$12:$B$251,$B9))) | S9: =IF($B9="","",IF(_xlfn.MINIFS('У8 Ввод'!$D$12:$D$251,'У8 Ввод'!$B$12:$B$251,$B9)=0,"",_xlfn.MINIFS('У8 Ввод'!$D$12:$D$251,'У8 Ввод'!$B$12:$B$251,$B9))) | T9: =IF($B9="","",IF(_xlfn.MAXIFS('У8 Ввод'!$F$12:$F$251,'У8 Ввод'!$B$12:$B$251,$B9)=0,"",_xlfn.MAXIFS('У8 Ввод'!$F$12:$F$251,'У8 Ввод'!$B$12:$B$251,$B9))) | U9: =IF($B9="","",IF(_xlfn.MINIFS('У9 Ввод'!$D$12:$D$251,'У9 Ввод'!$B$12:$B$251,$B9)=0,"",_xlfn.MINIFS('У9 Ввод'!$D$12:$D$251,'У9 Ввод'!$B$12:$B$251,$B9))) | V9: =IF($B9="","",IF(_xlfn.MAXIFS('У9 Ввод'!$F$12:$F$251,'У9 Ввод'!$B$12:$B$251,$B9)=0,"",_xlfn.MAXIFS('У9 Ввод'!$F$12:$F$251,'У9 Ввод'!$B$12:$B$251,$B9))) | W9: =IF($B9="","",IF(_xlfn.MINIFS('У10 Ввод'!$D$12:$D$251,'У10 Ввод'!$B$12:$B$251,$B9)=0,"",_xlfn.MINIFS('У10 Ввод'!$D$12:$D$251,'У10 Ввод'!$B$12:$B$251,$B9))) | X9: =IF($B9="","",IF(_xlfn.MAXIFS('У10 Ввод'!$F$12:$F$251,'У10 Ввод'!$B$12:$B$251,$B9)=0,"",_xlfn.MAXIFS('У10 Ввод'!$F$12:$F$251,'У10 Ввод'!$B$12:$B$251,$B9))) | Y9: =IF(COUNT(E9,G9,I9,K9,M9,O9,Q9,S9,U9,W9)=0,"",MIN(E9,G9,I9,K9,M9,O9,Q9,S9,U9,W9)) | Z9: =IF(COUNT(F9,H9,J9,L9,N9,P9,R9,T9,V9,X9)=0,"",MAX(F9,H9,J9,L9,N9,P9,R9,T9,V9,X9)) | AA9: =IF(OR(Y9="",Z9=""),"",Z9-Y9+1)
A10: 7 | B10: =IF('Реестр заказов'!B10="","",'Реестр заказов'!B10) | C10: =IF('Реестр заказов'!C10="","",'Реестр заказов'!C10) | D10: =IF('Реестр заказов'!E10="","",'Реестр заказов'!E10) | E10: =IF($B10="","",IF(_xlfn.MINIFS('У1 Ввод'!$D$12:$D$251,'У1 Ввод'!$B$12:$B$251,$B10)=0,"",_xlfn.MINIFS('У1 Ввод'!$D$12:$D$251,'У1 Ввод'!$B$12:$B$251,$B10))) | F10: =IF($B10="","",IF(_xlfn.MAXIFS('У1 Ввод'!$F$12:$F$251,'У1 Ввод'!$B$12:$B$251,$B10)=0,"",_xlfn.MAXIFS('У1 Ввод'!$F$12:$F$251,'У1 Ввод'!$B$12:$B$251,$B10))) | G10: =IF($B10="","",IF(_xlfn.MINIFS('У2 Ввод'!$D$12:$D$251,'У2 Ввод'!$B$12:$B$251,$B10)=0,"",_xlfn.MINIFS('У2 Ввод'!$D$12:$D$251,'У2 Ввод'!$B$12:$B$251,$B10))) | H10: =IF($B10="","",IF(_xlfn.MAXIFS('У2 Ввод'!$F$12:$F$251,'У2 Ввод'!$B$12:$B$251,$B10)=0,"",_xlfn.MAXIFS('У2 Ввод'!$F$12:$F$251,'У2 Ввод'!$B$12:$B$251,$B10))) | I10: =IF($B10="","",IF(_xlfn.MINIFS('У3 Ввод'!$D$12:$D$251,'У3 Ввод'!$B$12:$B$251,$B10)=0,"",_xlfn.MINIFS('У3 Ввод'!$D$12:$D$251,'У3 Ввод'!$B$12:$B$251,$B10))) | J10: =IF($B10="","",IF(_xlfn.MAXIFS('У3 Ввод'!$F$12:$F$251,'У3 Ввод'!$B$12:$B$251,$B10)=0,"",_xlfn.MAXIFS('У3 Ввод'!$F$12:$F$251,'У3 Ввод'!$B$12:$B$251,$B10))) | K10: =IF($B10="","",IF(_xlfn.MINIFS('У4 Ввод'!$D$12:$D$251,'У4 Ввод'!$B$12:$B$251,$B10)=0,"",_xlfn.MINIFS('У4 Ввод'!$D$12:$D$251,'У4 Ввод'!$B$12:$B$251,$B10))) | L10: =IF($B10="","",IF(_xlfn.MAXIFS('У4 Ввод'!$F$12:$F$251,'У4 Ввод'!$B$12:$B$251,$B10)=0,"",_xlfn.MAXIFS('У4 Ввод'!$F$12:$F$251,'У4 Ввод'!$B$12:$B$251,$B10))) | M10: =IF($B10="","",IF(_xlfn.MINIFS('У5 Ввод'!$D$12:$D$251,'У5 Ввод'!$B$12:$B$251,$B10)=0,"",_xlfn.MINIFS('У5 Ввод'!$D$12:$D$251,'У5 Ввод'!$B$12:$B$251,$B10))) | N10: =IF($B10="","",IF(_xlfn.MAXIFS('У5 Ввод'!$F$12:$F$251,'У5 Ввод'!$B$12:$B$251,$B10)=0,"",_xlfn.MAXIFS('У5 Ввод'!$F$12:$F$251,'У5 Ввод'!$B$12:$B$251,$B10))) | O10: =IF($B10="","",IF(_xlfn.MINIFS('У6 Ввод'!$D$12:$D$251,'У6 Ввод'!$B$12:$B$251,$B10)=0,"",_xlfn.MINIFS('У6 Ввод'!$D$12:$D$251,'У6 Ввод'!$B$12:$B$251,$B10))) | P10: =IF($B10="","",IF(_xlfn.MAXIFS('У6 Ввод'!$F$12:$F$251,'У6 Ввод'!$B$12:$B$251,$B10)=0,"",_xlfn.MAXIFS('У6 Ввод'!$F$12:$F$251,'У6 Ввод'!$B$12:$B$251,$B10))) | Q10: =IF($B10="","",IF(_xlfn.MINIFS('У7 Ввод'!$D$12:$D$251,'У7 Ввод'!$B$12:$B$251,$B10)=0,"",_xlfn.MINIFS('У7 Ввод'!$D$12:$D$251,'У7 Ввод'!$B$12:$B$251,$B10))) | R10: =IF($B10="","",IF(_xlfn.MAXIFS('У7 Ввод'!$F$12:$F$251,'У7 Ввод'!$B$12:$B$251,$B10)=0,"",_xlfn.MAXIFS('У7 Ввод'!$F$12:$F$251,'У7 Ввод'!$B$12:$B$251,$B10))) | S10: =IF($B10="","",IF(_xlfn.MINIFS('У8 Ввод'!$D$12:$D$251,'У8 Ввод'!$B$12:$B$251,$B10)=0,"",_xlfn.MINIFS('У8 Ввод'!$D$12:$D$251,'У8 Ввод'!$B$12:$B$251,$B10))) | T10: =IF($B10="","",IF(_xlfn.MAXIFS('У8 Ввод'!$F$12:$F$251,'У8 Ввод'!$B$12:$B$251,$B10)=0,"",_xlfn.MAXIFS('У8 Ввод'!$F$12:$F$251,'У8 Ввод'!$B$12:$B$251,$B10))) | U10: =IF($B10="","",IF(_xlfn.MINIFS('У9 Ввод'!$D$12:$D$251,'У9 Ввод'!$B$12:$B$251,$B10)=0,"",_xlfn.MINIFS('У9 Ввод'!$D$12:$D$251,'У9 Ввод'!$B$12:$B$251,$B10))) | V10: =IF($B10="","",IF(_xlfn.MAXIFS('У9 Ввод'!$F$12:$F$251,'У9 Ввод'!$B$12:$B$251,$B10)=0,"",_xlfn.MAXIFS('У9 Ввод'!$F$12:$F$251,'У9 Ввод'!$B$12:$B$251,$B10))) | W10: =IF($B10="","",IF(_xlfn.MINIFS('У10 Ввод'!$D$12:$D$251,'У10 Ввод'!$B$12:$B$251,$B10)=0,"",_xlfn.MINIFS('У10 Ввод'!$D$12:$D$251,'У10 Ввод'!$B$12:$B$251,$B10))) | X10: =IF($B10="","",IF(_xlfn.MAXIFS('У10 Ввод'!$F$12:$F$251,'У10 Ввод'!$B$12:$B$251,$B10)=0,"",_xlfn.MAXIFS('У10 Ввод'!$F$12:$F$251,'У10 Ввод'!$B$12:$B$251,$B10))) | Y10: =IF(COUNT(E10,G10,I10,K10,M10,O10,Q10,S10,U10,W10)=0,"",MIN(E10,G10,I10,K10,M10,O10,Q10,S10,U10,W10)) | Z10: =IF(COUNT(F10,H10,J10,L10,N10,P10,R10,T10,V10,X10)=0,"",MAX(F10,H10,J10,L10,N10,P10,R10,T10,V10,X10)) | AA10: =IF(OR(Y10="",Z10=""),"",Z10-Y10+1)
A11: 8 | B11: =IF('Реестр заказов'!B11="","",'Реестр заказов'!B11) | C11: =IF('Реестр заказов'!C11="","",'Реестр заказов'!C11) | D11: =IF('Реестр заказов'!E11="","",'Реестр заказов'!E11) | E11: =IF($B11="","",IF(_xlfn.MINIFS('У1 Ввод'!$D$12:$D$251,'У1 Ввод'!$B$12:$B$251,$B11)=0,"",_xlfn.MINIFS('У1 Ввод'!$D$12:$D$251,'У1 Ввод'!$B$12:$B$251,$B11))) | F11: =IF($B11="","",IF(_xlfn.MAXIFS('У1 Ввод'!$F$12:$F$251,'У1 Ввод'!$B$12:$B$251,$B11)=0,"",_xlfn.MAXIFS('У1 Ввод'!$F$12:$F$251,'У1 Ввод'!$B$12:$B$251,$B11))) | G11: =IF($B11="","",IF(_xlfn.MINIFS('У2 Ввод'!$D$12:$D$251,'У2 Ввод'!$B$12:$B$251,$B11)=0,"",_xlfn.MINIFS('У2 Ввод'!$D$12:$D$251,'У2 Ввод'!$B$12:$B$251,$B11))) | H11: =IF($B11="","",IF(_xlfn.MAXIFS('У2 Ввод'!$F$12:$F$251,'У2 Ввод'!$B$12:$B$251,$B11)=0,"",_xlfn.MAXIFS('У2 Ввод'!$F$12:$F$251,'У2 Ввод'!$B$12:$B$251,$B11))) | I11: =IF($B11="","",IF(_xlfn.MINIFS('У3 Ввод'!$D$12:$D$251,'У3 Ввод'!$B$12:$B$251,$B11)=0,"",_xlfn.MINIFS('У3 Ввод'!$D$12:$D$251,'У3 Ввод'!$B$12:$B$251,$B11))) | J11: =IF($B11="","",IF(_xlfn.MAXIFS('У3 Ввод'!$F$12:$F$251,'У3 Ввод'!$B$12:$B$251,$B11)=0,"",_xlfn.MAXIFS('У3 Ввод'!$F$12:$F$251,'У3 Ввод'!$B$12:$B$251,$B11))) | K11: =IF($B11="","",IF(_xlfn.MINIFS('У4 Ввод'!$D$12:$D$251,'У4 Ввод'!$B$12:$B$251,$B11)=0,"",_xlfn.MINIFS('У4 Ввод'!$D$12:$D$251,'У4 Ввод'!$B$12:$B$251,$B11))) | L11: =IF($B11="","",IF(_xlfn.MAXIFS('У4 Ввод'!$F$12:$F$251,'У4 Ввод'!$B$12:$B$251,$B11)=0,"",_xlfn.MAXIFS('У4 Ввод'!$F$12:$F$251,'У4 Ввод'!$B$12:$B$251,$B11))) | M11: =IF($B11="","",IF(_xlfn.MINIFS('У5 Ввод'!$D$12:$D$251,'У5 Ввод'!$B$12:$B$251,$B11)=0,"",_xlfn.MINIFS('У5 Ввод'!$D$12:$D$251,'У5 Ввод'!$B$12:$B$251,$B11))) | N11: =IF($B11="","",IF(_xlfn.MAXIFS('У5 Ввод'!$F$12:$F$251,'У5 Ввод'!$B$12:$B$251,$B11)=0,"",_xlfn.MAXIFS('У5 Ввод'!$F$12:$F$251,'У5 Ввод'!$B$12:$B$251,$B11))) | O11: =IF($B11="","",IF(_xlfn.MINIFS('У6 Ввод'!$D$12:$D$251,'У6 Ввод'!$B$12:$B$251,$B11)=0,"",_xlfn.MINIFS('У6 Ввод'!$D$12:$D$251,'У6 Ввод'!$B$12:$B$251,$B11))) | P11: =IF($B11="","",IF(_xlfn.MAXIFS('У6 Ввод'!$F$12:$F$251,'У6 Ввод'!$B$12:$B$251,$B11)=0,"",_xlfn.MAXIFS('У6 Ввод'!$F$12:$F$251,'У6 Ввод'!$B$12:$B$251,$B11))) | Q11: =IF($B11="","",IF(_xlfn.MINIFS('У7 Ввод'!$D$12:$D$251,'У7 Ввод'!$B$12:$B$251,$B11)=0,"",_xlfn.MINIFS('У7 Ввод'!$D$12:$D$251,'У7 Ввод'!$B$12:$B$251,$B11))) | R11: =IF($B11="","",IF(_xlfn.MAXIFS('У7 Ввод'!$F$12:$F$251,'У7 Ввод'!$B$12:$B$251,$B11)=0,"",_xlfn.MAXIFS('У7 Ввод'!$F$12:$F$251,'У7 Ввод'!$B$12:$B$251,$B11))) | S11: =IF($B11="","",IF(_xlfn.MINIFS('У8 Ввод'!$D$12:$D$251,'У8 Ввод'!$B$12:$B$251,$B11)=0,"",_xlfn.MINIFS('У8 Ввод'!$D$12:$D$251,'У8 Ввод'!$B$12:$B$251,$B11))) | T11: =IF($B11="","",IF(_xlfn.MAXIFS('У8 Ввод'!$F$12:$F$251,'У8 Ввод'!$B$12:$B$251,$B11)=0,"",_xlfn.MAXIFS('У8 Ввод'!$F$12:$F$251,'У8 Ввод'!$B$12:$B$251,$B11))) | U11: =IF($B11="","",IF(_xlfn.MINIFS('У9 Ввод'!$D$12:$D$251,'У9 Ввод'!$B$12:$B$251,$B11)=0,"",_xlfn.MINIFS('У9 Ввод'!$D$12:$D$251,'У9 Ввод'!$B$12:$B$251,$B11))) | V11: =IF($B11="","",IF(_xlfn.MAXIFS('У9 Ввод'!$F$12:$F$251,'У9 Ввод'!$B$12:$B$251,$B11)=0,"",_xlfn.MAXIFS('У9 Ввод'!$F$12:$F$251,'У9 Ввод'!$B$12:$B$251,$B11))) | W11: =IF($B11="","",IF(_xlfn.MINIFS('У10 Ввод'!$D$12:$D$251,'У10 Ввод'!$B$12:$B$251,$B11)=0,"",_xlfn.MINIFS('У10 Ввод'!$D$12:$D$251,'У10 Ввод'!$B$12:$B$251,$B11))) | X11: =IF($B11="","",IF(_xlfn.MAXIFS('У10 Ввод'!$F$12:$F$251,'У10 Ввод'!$B$12:$B$251,$B11)=0,"",_xlfn.MAXIFS('У10 Ввод'!$F$12:$F$251,'У10 Ввод'!$B$12:$B$251,$B11))) | Y11: =IF(COUNT(E11,G11,I11,K11,M11,O11,Q11,S11,U11,W11)=0,"",MIN(E11,G11,I11,K11,M11,O11,Q11,S11,U11,W11)) | Z11: =IF(COUNT(F11,H11,J11,L11,N11,P11,R11,T11,V11,X11)=0,"",MAX(F11,H11,J11,L11,N11,P11,R11,T11,V11,X11)) | AA11: =IF(OR(Y11="",Z11=""),"",Z11-Y11+1)
A12: 9 | B12: =IF('Реестр заказов'!B12="","",'Реестр заказов'!B12) | C12: =IF('Реестр заказов'!C12="","",'Реестр заказов'!C12) | D12: =IF('Реестр заказов'!E12="","",'Реестр заказов'!E12) | E12: =IF($B12="","",IF(_xlfn.MINIFS('У1 Ввод'!$D$12:$D$251,'У1 Ввод'!$B$12:$B$251,$B12)=0,"",_xlfn.MINIFS('У1 Ввод'!$D$12:$D$251,'У1 Ввод'!$B$12:$B$251,$B12))) | F12: =IF($B12="","",IF(_xlfn.MAXIFS('У1 Ввод'!$F$12:$F$251,'У1 Ввод'!$B$12:$B$251,$B12)=0,"",_xlfn.MAXIFS('У1 Ввод'!$F$12:$F$251,'У1 Ввод'!$B$12:$B$251,$B12))) | G12: =IF($B12="","",IF(_xlfn.MINIFS('У2 Ввод'!$D$12:$D$251,'У2 Ввод'!$B$12:$B$251,$B12)=0,"",_xlfn.MINIFS('У2 Ввод'!$D$12:$D$251,'У2 Ввод'!$B$12:$B$251,$B12))) | H12: =IF($B12="","",IF(_xlfn.MAXIFS('У2 Ввод'!$F$12:$F$251,'У2 Ввод'!$B$12:$B$251,$B12)=0,"",_xlfn.MAXIFS('У2 Ввод'!$F$12:$F$251,'У2 Ввод'!$B$12:$B$251,$B12))) | I12: =IF($B12="","",IF(_xlfn.MINIFS('У3 Ввод'!$D$12:$D$251,'У3 Ввод'!$B$12:$B$251,$B12)=0,"",_xlfn.MINIFS('У3 Ввод'!$D$12:$D$251,'У3 Ввод'!$B$12:$B$251,$B12))) | J12: =IF($B12="","",IF(_xlfn.MAXIFS('У3 Ввод'!$F$12:$F$251,'У3 Ввод'!$B$12:$B$251,$B12)=0,"",_xlfn.MAXIFS('У3 Ввод'!$F$12:$F$251,'У3 Ввод'!$B$12:$B$251,$B12))) | K12: =IF($B12="","",IF(_xlfn.MINIFS('У4 Ввод'!$D$12:$D$251,'У4 Ввод'!$B$12:$B$251,$B12)=0,"",_xlfn.MINIFS('У4 Ввод'!$D$12:$D$251,'У4 Ввод'!$B$12:$B$251,$B12))) | L12: =IF($B12="","",IF(_xlfn.MAXIFS('У4 Ввод'!$F$12:$F$251,'У4 Ввод'!$B$12:$B$251,$B12)=0,"",_xlfn.MAXIFS('У4 Ввод'!$F$12:$F$251,'У4 Ввод'!$B$12:$B$251,$B12))) | M12: =IF($B12="","",IF(_xlfn.MINIFS('У5 Ввод'!$D$12:$D$251,'У5 Ввод'!$B$12:$B$251,$B12)=0,"",_xlfn.MINIFS('У5 Ввод'!$D$12:$D$251,'У5 Ввод'!$B$12:$B$251,$B12))) | N12: =IF($B12="","",IF(_xlfn.MAXIFS('У5 Ввод'!$F$12:$F$251,'У5 Ввод'!$B$12:$B$251,$B12)=0,"",_xlfn.MAXIFS('У5 Ввод'!$F$12:$F$251,'У5 Ввод'!$B$12:$B$251,$B12))) | O12: =IF($B12="","",IF(_xlfn.MINIFS('У6 Ввод'!$D$12:$D$251,'У6 Ввод'!$B$12:$B$251,$B12)=0,"",_xlfn.MINIFS('У6 Ввод'!$D$12:$D$251,'У6 Ввод'!$B$12:$B$251,$B12))) | P12: =IF($B12="","",IF(_xlfn.MAXIFS('У6 Ввод'!$F$12:$F$251,'У6 Ввод'!$B$12:$B$251,$B12)=0,"",_xlfn.MAXIFS('У6 Ввод'!$F$12:$F$251,'У6 Ввод'!$B$12:$B$251,$B12))) | Q12: =IF($B12="","",IF(_xlfn.MINIFS('У7 Ввод'!$D$12:$D$251,'У7 Ввод'!$B$12:$B$251,$B12)=0,"",_xlfn.MINIFS('У7 Ввод'!$D$12:$D$251,'У7 Ввод'!$B$12:$B$251,$B12))) | R12: =IF($B12="","",IF(_xlfn.MAXIFS('У7 Ввод'!$F$12:$F$251,'У7 Ввод'!$B$12:$B$251,$B12)=0,"",_xlfn.MAXIFS('У7 Ввод'!$F$12:$F$251,'У7 Ввод'!$B$12:$B$251,$B12))) | S12: =IF($B12="","",IF(_xlfn.MINIFS('У8 Ввод'!$D$12:$D$251,'У8 Ввод'!$B$12:$B$251,$B12)=0,"",_xlfn.MINIFS('У8 Ввод'!$D$12:$D$251,'У8 Ввод'!$B$12:$B$251,$B12))) | T12: =IF($B12="","",IF(_xlfn.MAXIFS('У8 Ввод'!$F$12:$F$251,'У8 Ввод'!$B$12:$B$251,$B12)=0,"",_xlfn.MAXIFS('У8 Ввод'!$F$12:$F$251,'У8 Ввод'!$B$12:$B$251,$B12))) | U12: =IF($B12="","",IF(_xlfn.MINIFS('У9 Ввод'!$D$12:$D$251,'У9 Ввод'!$B$12:$B$251,$B12)=0,"",_xlfn.MINIFS('У9 Ввод'!$D$12:$D$251,'У9 Ввод'!$B$12:$B$251,$B12))) | V12: =IF($B12="","",IF(_xlfn.MAXIFS('У9 Ввод'!$F$12:$F$251,'У9 Ввод'!$B$12:$B$251,$B12)=0,"",_xlfn.MAXIFS('У9 Ввод'!$F$12:$F$251,'У9 Ввод'!$B$12:$B$251,$B12))) | W12: =IF($B12="","",IF(_xlfn.MINIFS('У10 Ввод'!$D$12:$D$251,'У10 Ввод'!$B$12:$B$251,$B12)=0,"",_xlfn.MINIFS('У10 Ввод'!$D$12:$D$251,'У10 Ввод'!$B$12:$B$251,$B12))) | X12: =IF($B12="","",IF(_xlfn.MAXIFS('У10 Ввод'!$F$12:$F$251,'У10 Ввод'!$B$12:$B$251,$B12)=0,"",_xlfn.MAXIFS('У10 Ввод'!$F$12:$F$251,'У10 Ввод'!$B$12:$B$251,$B12))) | Y12: =IF(COUNT(E12,G12,I12,K12,M12,O12,Q12,S12,U12,W12)=0,"",MIN(E12,G12,I12,K12,M12,O12,Q12,S12,U12,W12)) | Z12: =IF(COUNT(F12,H12,J12,L12,N12,P12,R12,T12,V12,X12)=0,"",MAX(F12,H12,J12,L12,N12,P12,R12,T12,V12,X12)) | AA12: =IF(OR(Y12="",Z12=""),"",Z12-Y12+1)
A13: 10 | B13: =IF('Реестр заказов'!B13="","",'Реестр заказов'!B13) | C13: =IF('Реестр заказов'!C13="","",'Реестр заказов'!C13) | D13: =IF('Реестр заказов'!E13="","",'Реестр заказов'!E13) | E13: =IF($B13="","",IF(_xlfn.MINIFS('У1 Ввод'!$D$12:$D$251,'У1 Ввод'!$B$12:$B$251,$B13)=0,"",_xlfn.MINIFS('У1 Ввод'!$D$12:$D$251,'У1 Ввод'!$B$12:$B$251,$B13))) | F13: =IF($B13="","",IF(_xlfn.MAXIFS('У1 Ввод'!$F$12:$F$251,'У1 Ввод'!$B$12:$B$251,$B13)=0,"",_xlfn.MAXIFS('У1 Ввод'!$F$12:$F$251,'У1 Ввод'!$B$12:$B$251,$B13))) | G13: =IF($B13="","",IF(_xlfn.MINIFS('У2 Ввод'!$D$12:$D$251,'У2 Ввод'!$B$12:$B$251,$B13)=0,"",_xlfn.MINIFS('У2 Ввод'!$D$12:$D$251,'У2 Ввод'!$B$12:$B$251,$B13))) | H13: =IF($B13="","",IF(_xlfn.MAXIFS('У2 Ввод'!$F$12:$F$251,'У2 Ввод'!$B$12:$B$251,$B13)=0,"",_xlfn.MAXIFS('У2 Ввод'!$F$12:$F$251,'У2 Ввод'!$B$12:$B$251,$B13))) | I13: =IF($B13="","",IF(_xlfn.MINIFS('У3 Ввод'!$D$12:$D$251,'У3 Ввод'!$B$12:$B$251,$B13)=0,"",_xlfn.MINIFS('У3 Ввод'!$D$12:$D$251,'У3 Ввод'!$B$12:$B$251,$B13))) | J13: =IF($B13="","",IF(_xlfn.MAXIFS('У3 Ввод'!$F$12:$F$251,'У3 Ввод'!$B$12:$B$251,$B13)=0,"",_xlfn.MAXIFS('У3 Ввод'!$F$12:$F$251,'У3 Ввод'!$B$12:$B$251,$B13))) | K13: =IF($B13="","",IF(_xlfn.MINIFS('У4 Ввод'!$D$12:$D$251,'У4 Ввод'!$B$12:$B$251,$B13)=0,"",_xlfn.MINIFS('У4 Ввод'!$D$12:$D$251,'У4 Ввод'!$B$12:$B$251,$B13))) | L13: =IF($B13="","",IF(_xlfn.MAXIFS('У4 Ввод'!$F$12:$F$251,'У4 Ввод'!$B$12:$B$251,$B13)=0,"",_xlfn.MAXIFS('У4 Ввод'!$F$12:$F$251,'У4 Ввод'!$B$12:$B$251,$B13))) | M13: =IF($B13="","",IF(_xlfn.MINIFS('У5 Ввод'!$D$12:$D$251,'У5 Ввод'!$B$12:$B$251,$B13)=0,"",_xlfn.MINIFS('У5 Ввод'!$D$12:$D$251,'У5 Ввод'!$B$12:$B$251,$B13))) | N13: =IF($B13="","",IF(_xlfn.MAXIFS('У5 Ввод'!$F$12:$F$251,'У5 Ввод'!$B$12:$B$251,$B13)=0,"",_xlfn.MAXIFS('У5 Ввод'!$F$12:$F$251,'У5 Ввод'!$B$12:$B$251,$B13))) | O13: =IF($B13="","",IF(_xlfn.MINIFS('У6 Ввод'!$D$12:$D$251,'У6 Ввод'!$B$12:$B$251,$B13)=0,"",_xlfn.MINIFS('У6 Ввод'!$D$12:$D$251,'У6 Ввод'!$B$12:$B$251,$B13))) | P13: =IF($B13="","",IF(_xlfn.MAXIFS('У6 Ввод'!$F$12:$F$251,'У6 Ввод'!$B$12:$B$251,$B13)=0,"",_xlfn.MAXIFS('У6 Ввод'!$F$12:$F$251,'У6 Ввод'!$B$12:$B$251,$B13))) | Q13: =IF($B13="","",IF(_xlfn.MINIFS('У7 Ввод'!$D$12:$D$251,'У7 Ввод'!$B$12:$B$251,$B13)=0,"",_xlfn.MINIFS('У7 Ввод'!$D$12:$D$251,'У7 Ввод'!$B$12:$B$251,$B13))) | R13: =IF($B13="","",IF(_xlfn.MAXIFS('У7 Ввод'!$F$12:$F$251,'У7 Ввод'!$B$12:$B$251,$B13)=0,"",_xlfn.MAXIFS('У7 Ввод'!$F$12:$F$251,'У7 Ввод'!$B$12:$B$251,$B13))) | S13: =IF($B13="","",IF(_xlfn.MINIFS('У8 Ввод'!$D$12:$D$251,'У8 Ввод'!$B$12:$B$251,$B13)=0,"",_xlfn.MINIFS('У8 Ввод'!$D$12:$D$251,'У8 Ввод'!$B$12:$B$251,$B13))) | T13: =IF($B13="","",IF(_xlfn.MAXIFS('У8 Ввод'!$F$12:$F$251,'У8 Ввод'!$B$12:$B$251,$B13)=0,"",_xlfn.MAXIFS('У8 Ввод'!$F$12:$F$251,'У8 Ввод'!$B$12:$B$251,$B13))) | U13: =IF($B13="","",IF(_xlfn.MINIFS('У9 Ввод'!$D$12:$D$251,'У9 Ввод'!$B$12:$B$251,$B13)=0,"",_xlfn.MINIFS('У9 Ввод'!$D$12:$D$251,'У9 Ввод'!$B$12:$B$251,$B13))) | V13: =IF($B13="","",IF(_xlfn.MAXIFS('У9 Ввод'!$F$12:$F$251,'У9 Ввод'!$B$12:$B$251,$B13)=0,"",_xlfn.MAXIFS('У9 Ввод'!$F$12:$F$251,'У9 Ввод'!$B$12:$B$251,$B13))) | W13: =IF($B13="","",IF(_xlfn.MINIFS('У10 Ввод'!$D$12:$D$251,'У10 Ввод'!$B$12:$B$251,$B13)=0,"",_xlfn.MINIFS('У10 Ввод'!$D$12:$D$251,'У10 Ввод'!$B$12:$B$251,$B13))) | X13: =IF($B13="","",IF(_xlfn.MAXIFS('У10 Ввод'!$F$12:$F$251,'У10 Ввод'!$B$12:$B$251,$B13)=0,"",_xlfn.MAXIFS('У10 Ввод'!$F$12:$F$251,'У10 Ввод'!$B$12:$B$251,$B13))) | Y13: =IF(COUNT(E13,G13,I13,K13,M13,O13,Q13,S13,U13,W13)=0,"",MIN(E13,G13,I13,K13,M13,O13,Q13,S13,U13,W13)) | Z13: =IF(COUNT(F13,H13,J13,L13,N13,P13,R13,T13,V13,X13)=0,"",MAX(F13,H13,J13,L13,N13,P13,R13,T13,V13,X13)) | AA13: =IF(OR(Y13="",Z13=""),"",Z13-Y13+1)
A14: 11 | B14: =IF('Реестр заказов'!B14="","",'Реестр заказов'!B14) | C14: =IF('Реестр заказов'!C14="","",'Реестр заказов'!C14) | D14: =IF('Реестр заказов'!E14="","",'Реестр заказов'!E14) | E14: =IF($B14="","",IF(_xlfn.MINIFS('У1 Ввод'!$D$12:$D$251,'У1 Ввод'!$B$12:$B$251,$B14)=0,"",_xlfn.MINIFS('У1 Ввод'!$D$12:$D$251,'У1 Ввод'!$B$12:$B$251,$B14))) | F14: =IF($B14="","",IF(_xlfn.MAXIFS('У1 Ввод'!$F$12:$F$251,'У1 Ввод'!$B$12:$B$251,$B14)=0,"",_xlfn.MAXIFS('У1 Ввод'!$F$12:$F$251,'У1 Ввод'!$B$12:$B$251,$B14))) | G14: =IF($B14="","",IF(_xlfn.MINIFS('У2 Ввод'!$D$12:$D$251,'У2 Ввод'!$B$12:$B$251,$B14)=0,"",_xlfn.MINIFS('У2 Ввод'!$D$12:$D$251,'У2 Ввод'!$B$12:$B$251,$B14))) | H14: =IF($B14="","",IF(_xlfn.MAXIFS('У2 Ввод'!$F$12:$F$251,'У2 Ввод'!$B$12:$B$251,$B14)=0,"",_xlfn.MAXIFS('У2 Ввод'!$F$12:$F$251,'У2 Ввод'!$B$12:$B$251,$B14))) | I14: =IF($B14="","",IF(_xlfn.MINIFS('У3 Ввод'!$D$12:$D$251,'У3 Ввод'!$B$12:$B$251,$B14)=0,"",_xlfn.MINIFS('У3 Ввод'!$D$12:$D$251,'У3 Ввод'!$B$12:$B$251,$B14))) | J14: =IF($B14="","",IF(_xlfn.MAXIFS('У3 Ввод'!$F$12:$F$251,'У3 Ввод'!$B$12:$B$251,$B14)=0,"",_xlfn.MAXIFS('У3 Ввод'!$F$12:$F$251,'У3 Ввод'!$B$12:$B$251,$B14))) | K14: =IF($B14="","",IF(_xlfn.MINIFS('У4 Ввод'!$D$12:$D$251,'У4 Ввод'!$B$12:$B$251,$B14)=0,"",_xlfn.MINIFS('У4 Ввод'!$D$12:$D$251,'У4 Ввод'!$B$12:$B$251,$B14))) | L14: =IF($B14="","",IF(_xlfn.MAXIFS('У4 Ввод'!$F$12:$F$251,'У4 Ввод'!$B$12:$B$251,$B14)=0,"",_xlfn.MAXIFS('У4 Ввод'!$F$12:$F$251,'У4 Ввод'!$B$12:$B$251,$B14))) | M14: =IF($B14="","",IF(_xlfn.MINIFS('У5 Ввод'!$D$12:$D$251,'У5 Ввод'!$B$12:$B$251,$B14)=0,"",_xlfn.MINIFS('У5 Ввод'!$D$12:$D$251,'У5 Ввод'!$B$12:$B$251,$B14))) | N14: =IF($B14="","",IF(_xlfn.MAXIFS('У5 Ввод'!$F$12:$F$251,'У5 Ввод'!$B$12:$B$251,$B14)=0,"",_xlfn.MAXIFS('У5 Ввод'!$F$12:$F$251,'У5 Ввод'!$B$12:$B$251,$B14))) | O14: =IF($B14="","",IF(_xlfn.MINIFS('У6 Ввод'!$D$12:$D$251,'У6 Ввод'!$B$12:$B$251,$B14)=0,"",_xlfn.MINIFS('У6 Ввод'!$D$12:$D$251,'У6 Ввод'!$B$12:$B$251,$B14))) | P14: =IF($B14="","",IF(_xlfn.MAXIFS('У6 Ввод'!$F$12:$F$251,'У6 Ввод'!$B$12:$B$251,$B14)=0,"",_xlfn.MAXIFS('У6 Ввод'!$F$12:$F$251,'У6 Ввод'!$B$12:$B$251,$B14))) | Q14: =IF($B14="","",IF(_xlfn.MINIFS('У7 Ввод'!$D$12:$D$251,'У7 Ввод'!$B$12:$B$251,$B14)=0,"",_xlfn.MINIFS('У7 Ввод'!$D$12:$D$251,'У7 Ввод'!$B$12:$B$251,$B14))) | R14: =IF($B14="","",IF(_xlfn.MAXIFS('У7 Ввод'!$F$12:$F$251,'У7 Ввод'!$B$12:$B$251,$B14)=0,"",_xlfn.MAXIFS('У7 Ввод'!$F$12:$F$251,'У7 Ввод'!$B$12:$B$251,$B14))) | S14: =IF($B14="","",IF(_xlfn.MINIFS('У8 Ввод'!$D$12:$D$251,'У8 Ввод'!$B$12:$B$251,$B14)=0,"",_xlfn.MINIFS('У8 Ввод'!$D$12:$D$251,'У8 Ввод'!$B$12:$B$251,$B14))) | T14: =IF($B14="","",IF(_xlfn.MAXIFS('У8 Ввод'!$F$12:$F$251,'У8 Ввод'!$B$12:$B$251,$B14)=0,"",_xlfn.MAXIFS('У8 Ввод'!$F$12:$F$251,'У8 Ввод'!$B$12:$B$251,$B14))) | U14: =IF($B14="","",IF(_xlfn.MINIFS('У9 Ввод'!$D$12:$D$251,'У9 Ввод'!$B$12:$B$251,$B14)=0,"",_xlfn.MINIFS('У9 Ввод'!$D$12:$D$251,'У9 Ввод'!$B$12:$B$251,$B14))) | V14: =IF($B14="","",IF(_xlfn.MAXIFS('У9 Ввод'!$F$12:$F$251,'У9 Ввод'!$B$12:$B$251,$B14)=0,"",_xlfn.MAXIFS('У9 Ввод'!$F$12:$F$251,'У9 Ввод'!$B$12:$B$251,$B14))) | W14: =IF($B14="","",IF(_xlfn.MINIFS('У10 Ввод'!$D$12:$D$251,'У10 Ввод'!$B$12:$B$251,$B14)=0,"",_xlfn.MINIFS('У10 Ввод'!$D$12:$D$251,'У10 Ввод'!$B$12:$B$251,$B14))) | X14: =IF($B14="","",IF(_xlfn.MAXIFS('У10 Ввод'!$F$12:$F$251,'У10 Ввод'!$B$12:$B$251,$B14)=0,"",_xlfn.MAXIFS('У10 Ввод'!$F$12:$F$251,'У10 Ввод'!$B$12:$B$251,$B14))) | Y14: =IF(COUNT(E14,G14,I14,K14,M14,O14,Q14,S14,U14,W14)=0,"",MIN(E14,G14,I14,K14,M14,O14,Q14,S14,U14,W14)) | Z14: =IF(COUNT(F14,H14,J14,L14,N14,P14,R14,T14,V14,X14)=0,"",MAX(F14,H14,J14,L14,N14,P14,R14,T14,V14,X14)) | AA14: =IF(OR(Y14="",Z14=""),"",Z14-Y14+1)
A15: 12 | B15: =IF('Реестр заказов'!B15="","",'Реестр заказов'!B15) | C15: =IF('Реестр заказов'!C15="","",'Реестр заказов'!C15) | D15: =IF('Реестр заказов'!E15="","",'Реестр заказов'!E15) | E15: =IF($B15="","",IF(_xlfn.MINIFS('У1 Ввод'!$D$12:$D$251,'У1 Ввод'!$B$12:$B$251,$B15)=0,"",_xlfn.MINIFS('У1 Ввод'!$D$12:$D$251,'У1 Ввод'!$B$12:$B$251,$B15))) | F15: =IF($B15="","",IF(_xlfn.MAXIFS('У1 Ввод'!$F$12:$F$251,'У1 Ввод'!$B$12:$B$251,$B15)=0,"",_xlfn.MAXIFS('У1 Ввод'!$F$12:$F$251,'У1 Ввод'!$B$12:$B$251,$B15))) | G15: =IF($B15="","",IF(_xlfn.MINIFS('У2 Ввод'!$D$12:$D$251,'У2 Ввод'!$B$12:$B$251,$B15)=0,"",_xlfn.MINIFS('У2 Ввод'!$D$12:$D$251,'У2 Ввод'!$B$12:$B$251,$B15))) | H15: =IF($B15="","",IF(_xlfn.MAXIFS('У2 Ввод'!$F$12:$F$251,'У2 Ввод'!$B$12:$B$251,$B15)=0,"",_xlfn.MAXIFS('У2 Ввод'!$F$12:$F$251,'У2 Ввод'!$B$12:$B$251,$B15))) | I15: =IF($B15="","",IF(_xlfn.MINIFS('У3 Ввод'!$D$12:$D$251,'У3 Ввод'!$B$12:$B$251,$B15)=0,"",_xlfn.MINIFS('У3 Ввод'!$D$12:$D$251,'У3 Ввод'!$B$12:$B$251,$B15))) | J15: =IF($B15="","",IF(_xlfn.MAXIFS('У3 Ввод'!$F$12:$F$251,'У3 Ввод'!$B$12:$B$251,$B15)=0,"",_xlfn.MAXIFS('У3 Ввод'!$F$12:$F$251,'У3 Ввод'!$B$12:$B$251,$B15))) | K15: =IF($B15="","",IF(_xlfn.MINIFS('У4 Ввод'!$D$12:$D$251,'У4 Ввод'!$B$12:$B$251,$B15)=0,"",_xlfn.MINIFS('У4 Ввод'!$D$12:$D$251,'У4 Ввод'!$B$12:$B$251,$B15))) | L15: =IF($B15="","",IF(_xlfn.MAXIFS('У4 Ввод'!$F$12:$F$251,'У4 Ввод'!$B$12:$B$251,$B15)=0,"",_xlfn.MAXIFS('У4 Ввод'!$F$12:$F$251,'У4 Ввод'!$B$12:$B$251,$B15))) | M15: =IF($B15="","",IF(_xlfn.MINIFS('У5 Ввод'!$D$12:$D$251,'У5 Ввод'!$B$12:$B$251,$B15)=0,"",_xlfn.MINIFS('У5 Ввод'!$D$12:$D$251,'У5 Ввод'!$B$12:$B$251,$B15))) | N15: =IF($B15="","",IF(_xlfn.MAXIFS('У5 Ввод'!$F$12:$F$251,'У5 Ввод'!$B$12:$B$251,$B15)=0,"",_xlfn.MAXIFS('У5 Ввод'!$F$12:$F$251,'У5 Ввод'!$B$12:$B$251,$B15))) | O15: =IF($B15="","",IF(_xlfn.MINIFS('У6 Ввод'!$D$12:$D$251,'У6 Ввод'!$B$12:$B$251,$B15)=0,"",_xlfn.MINIFS('У6 Ввод'!$D$12:$D$251,'У6 Ввод'!$B$12:$B$251,$B15))) | P15: =IF($B15="","",IF(_xlfn.MAXIFS('У6 Ввод'!$F$12:$F$251,'У6 Ввод'!$B$12:$B$251,$B15)=0,"",_xlfn.MAXIFS('У6 Ввод'!$F$12:$F$251,'У6 Ввод'!$B$12:$B$251,$B15))) | Q15: =IF($B15="","",IF(_xlfn.MINIFS('У7 Ввод'!$D$12:$D$251,'У7 Ввод'!$B$12:$B$251,$B15)=0,"",_xlfn.MINIFS('У7 Ввод'!$D$12:$D$251,'У7 Ввод'!$B$12:$B$251,$B15))) | R15: =IF($B15="","",IF(_xlfn.MAXIFS('У7 Ввод'!$F$12:$F$251,'У7 Ввод'!$B$12:$B$251,$B15)=0,"",_xlfn.MAXIFS('У7 Ввод'!$F$12:$F$251,'У7 Ввод'!$B$12:$B$251,$B15))) | S15: =IF($B15="","",IF(_xlfn.MINIFS('У8 Ввод'!$D$12:$D$251,'У8 Ввод'!$B$12:$B$251,$B15)=0,"",_xlfn.MINIFS('У8 Ввод'!$D$12:$D$251,'У8 Ввод'!$B$12:$B$251,$B15))) | T15: =IF($B15="","",IF(_xlfn.MAXIFS('У8 Ввод'!$F$12:$F$251,'У8 Ввод'!$B$12:$B$251,$B15)=0,"",_xlfn.MAXIFS('У8 Ввод'!$F$12:$F$251,'У8 Ввод'!$B$12:$B$251,$B15))) | U15: =IF($B15="","",IF(_xlfn.MINIFS('У9 Ввод'!$D$12:$D$251,'У9 Ввод'!$B$12:$B$251,$B15)=0,"",_xlfn.MINIFS('У9 Ввод'!$D$12:$D$251,'У9 Ввод'!$B$12:$B$251,$B15))) | V15: =IF($B15="","",IF(_xlfn.MAXIFS('У9 Ввод'!$F$12:$F$251,'У9 Ввод'!$B$12:$B$251,$B15)=0,"",_xlfn.MAXIFS('У9 Ввод'!$F$12:$F$251,'У9 Ввод'!$B$12:$B$251,$B15))) | W15: =IF($B15="","",IF(_xlfn.MINIFS('У10 Ввод'!$D$12:$D$251,'У10 Ввод'!$B$12:$B$251,$B15)=0,"",_xlfn.MINIFS('У10 Ввод'!$D$12:$D$251,'У10 Ввод'!$B$12:$B$251,$B15))) | X15: =IF($B15="","",IF(_xlfn.MAXIFS('У10 Ввод'!$F$12:$F$251,'У10 Ввод'!$B$12:$B$251,$B15)=0,"",_xlfn.MAXIFS('У10 Ввод'!$F$12:$F$251,'У10 Ввод'!$B$12:$B$251,$B15))) | Y15: =IF(COUNT(E15,G15,I15,K15,M15,O15,Q15,S15,U15,W15)=0,"",MIN(E15,G15,I15,K15,M15,O15,Q15,S15,U15,W15)) | Z15: =IF(COUNT(F15,H15,J15,L15,N15,P15,R15,T15,V15,X15)=0,"",MAX(F15,H15,J15,L15,N15,P15,R15,T15,V15,X15)) | AA15: =IF(OR(Y15="",Z15=""),"",Z15-Y15+1)
... A33: 30 | B33: =IF('Реестр заказов'!B33="","",'Реестр заказов'!B33) | C33: =IF('Реестр заказов'!C33="","",'Реестр заказов'!C33) | D33: =IF('Реестр заказов'!E33="","",'Реестр заказов'!E33) | E33: =IF($B33="","",IF(_xlfn.MINIFS('У1 Ввод'!$D$12:$D$251,'У1 Ввод'!$B$12:$B$251,$B33)=0,"",_xlfn.MINIFS('У1 Ввод'!$D$12:$D$251,'У1 Ввод'!$B$12:$B$251,$B33))) | F33: =IF($B33="","",IF(_xlfn.MAXIFS('У1 Ввод'!$F$12:$F$251,'У1 Ввод'!$B$12:$B$251,$B33)=0,"",_xlfn.MAXIFS('У1 Ввод'!$F$12:$F$251,'У1 Ввод'!$B$12:$B$251,$B33))) | G33: =IF($B33="","",IF(_xlfn.MINIFS('У2 Ввод'!$D$12:$D$251,'У2 Ввод'!$B$12:$B$251,$B33)=0,"",_xlfn.MINIFS('У2 Ввод'!$D$12:$D$251,'У2 Ввод'!$B$12:$B$251,$B33))) | H33: =IF($B33="","",IF(_xlfn.MAXIFS('У2 Ввод'!$F$12:$F$251,'У2 Ввод'!$B$12:$B$251,$B33)=0,"",_xlfn.MAXIFS('У2 Ввод'!$F$12:$F$251,'У2 Ввод'!$B$12:$B$251,$B33))) | I33: =IF($B33="","",IF(_xlfn.MINIFS('У3 Ввод'!$D$12:$D$251,'У3 Ввод'!$B$12:$B$251,$B33)=0,"",_xlfn.MINIFS('У3 Ввод'!$D$12:$D$251,'У3 Ввод'!$B$12:$B$251,$B33))) | J33: =IF($B33="","",IF(_xlfn.MAXIFS('У3 Ввод'!$F$12:$F$251,'У3 Ввод'!$B$12:$B$251,$B33)=0,"",_xlfn.MAXIFS('У3 Ввод'!$F$12:$F$251,'У3 Ввод'!$B$12:$B$251,$B33))) | K33: =IF($B33="","",IF(_xlfn.MINIFS('У4 Ввод'!$D$12:$D$251,'У4 Ввод'!$B$12:$B$251,$B33)=0,"",_xlfn.MINIFS('У4 Ввод'!$D$12:$D$251,'У4 Ввод'!$B$12:$B$251,$B33))) | L33: =IF($B33="","",IF(_xlfn.MAXIFS('У4 Ввод'!$F$12:$F$251,'У4 Ввод'!$B$12:$B$251,$B33)=0,"",_xlfn.MAXIFS('У4 Ввод'!$F$12:$F$251,'У4 Ввод'!$B$12:$B$251,$B33))) | M33: =IF($B33="","",IF(_xlfn.MINIFS('У5 Ввод'!$D$12:$D$251,'У5 Ввод'!$B$12:$B$251,$B33)=0,"",_xlfn.MINIFS('У5 Ввод'!$D$12:$D$251,'У5 Ввод'!$B$12:$B$251,$B33))) | N33: =IF($B33="","",IF(_xlfn.MAXIFS('У5 Ввод'!$F$12:$F$251,'У5 Ввод'!$B$12:$B$251,$B33)=0,"",_xlfn.MAXIFS('У5 Ввод'!$F$12:$F$251,'У5 Ввод'!$B$12:$B$251,$B33))) | O33: =IF($B33="","",IF(_xlfn.MINIFS('У6 Ввод'!$D$12:$D$251,'У6 Ввод'!$B$12:$B$251,$B33)=0,"",_xlfn.MINIFS('У6 Ввод'!$D$12:$D$251,'У6 Ввод'!$B$12:$B$251,$B33))) | P33: =IF($B33="","",IF(_xlfn.MAXIFS('У6 Ввод'!$F$12:$F$251,'У6 Ввод'!$B$12:$B$251,$B33)=0,"",_xlfn.MAXIFS('У6 Ввод'!$F$12:$F$251,'У6 Ввод'!$B$12:$B$251,$B33))) | Q33: =IF($B33="","",IF(_xlfn.MINIFS('У7 Ввод'!$D$12:$D$251,'У7 Ввод'!$B$12:$B$251,$B33)=0,"",_xlfn.MINIFS('У7 Ввод'!$D$12:$D$251,'У7 Ввод'!$B$12:$B$251,$B33))) | R33: =IF($B33="","",IF(_xlfn.MAXIFS('У7 Ввод'!$F$12:$F$251,'У7 Ввод'!$B$12:$B$251,$B33)=0,"",_xlfn.MAXIFS('У7 Ввод'!$F$12:$F$251,'У7 Ввод'!$B$12:$B$251,$B33))) | S33: =IF($B33="","",IF(_xlfn.MINIFS('У8 Ввод'!$D$12:$D$251,'У8 Ввод'!$B$12:$B$251,$B33)=0,"",_xlfn.MINIFS('У8 Ввод'!$D$12:$D$251,'У8 Ввод'!$B$12:$B$251,$B33))) | T33: =IF($B33="","",IF(_xlfn.MAXIFS('У8 Ввод'!$F$12:$F$251,'У8 Ввод'!$B$12:$B$251,$B33)=0,"",_xlfn.MAXIFS('У8 Ввод'!$F$12:$F$251,'У8 Ввод'!$B$12:$B$251,$B33))) | U33: =IF($B33="","",IF(_xlfn.MINIFS('У9 Ввод'!$D$12:$D$251,'У9 Ввод'!$B$12:$B$251,$B33)=0,"",_xlfn.MINIFS('У9 Ввод'!$D$12:$D$251,'У9 Ввод'!$B$12:$B$251,$B33))) | V33: =IF($B33="","",IF(_xlfn.MAXIFS('У9 Ввод'!$F$12:$F$251,'У9 Ввод'!$B$12:$B$251,$B33)=0,"",_xlfn.MAXIFS('У9 Ввод'!$F$12:$F$251,'У9 Ввод'!$B$12:$B$251,$B33))) | W33: =IF($B33="","",IF(_xlfn.MINIFS('У10 Ввод'!$D$12:$D$251,'У10 Ввод'!$B$12:$B$251,$B33)=0,"",_xlfn.MINIFS('У10 Ввод'!$D$12:$D$251,'У10 Ввод'!$B$12:$B$251,$B33))) | X33: =IF($B33="","",IF(_xlfn.MAXIFS('У10 Ввод'!$F$12:$F$251,'У10 Ввод'!$B$12:$B$251,$B33)=0,"",_xlfn.MAXIFS('У10 Ввод'!$F$12:$F$251,'У10 Ввод'!$B$12:$B$251,$B33))) | Y33: =IF(COUNT(E33,G33,I33,K33,M33,O33,Q33,S33,U33,W33)=0,"",MIN(E33,G33,I33,K33,M33,O33,Q33,S33,U33,W33)) | Z33: =IF(COUNT(F33,H33,J33,L33,N33,P33,R33,T33,V33,X33)=0,"",MAX(F33,H33,J33,L33,N33,P33,R33,T33,V33,X33)) | AA33: =IF(OR(Y33="",Z33=""),"",Z33-Y33+1)

Sheet Мастер-график
A1: МАСТЕР-ГРАФИК — ПОЛНЫЙ ПРОИЗВОДСТВЕННЫЙ ЦИКЛ: от разработки КД до сдачи на склад ГП
A2: Ниже — демо-визуализация. Живой мастер-гант строится и обновляется скриптом (меню «📊 Планирование» → «Обновить всё»).
A4: Заказ | B4: 01 | C4: 02 | D4: 03 | E4: 04 | F4: 05 | G4: 06 | H4: 07 | I4: 08 | J4: 09 | K4: 10 | L4: 11 | M4: 12 | N4: 13 | O4: 14 | P4: 15 | Q4: 16 | R4: 17 | S4: 18 | T4: 19 | U4: 20 | V4: 21 | W4: 22 | X4: 23 | Y4: 24 | Z4: 25 | AA4: 26 | AB4: 27 | AC4: 28 | AD4: 29 | AE4: 30 | AF4: 31
A5: 26-1817 | B5: У1 | D5: У2 | G5: У3 | H5: У6 | I5: У5 | P5: У7 | R5: У8 | W5: У9 | AB5: У10
A6: 26-1455 | C6: У1 | G6: У2 | H6: У6 | J6: У4 | Q6: У7 | U6: У8 | X6: У9 | AD6: У10
A7: 26-1905 | G7: У1 | N7: У3 | U7: У6 | AE7: У10
A10: Легенда:
A11: У1 | B11: =Настройки!$B$7 -> Конструкторское бюро | D11: У2 | E11: =Настройки!$B$8 -> Снабжение | G11: У3 | H11: =Настройки!$B$9 -> Лазерная резка | J11: У4 | K11: =Настройки!$B$10 -> Гибка | M11: У5 | N11: =Настройки!$B$11 -> Механообработка
A12: У6 | B12: =Настройки!$B$12 -> Сварка | D12: У7 | E12: =Настройки!$B$13 -> Окраска | G12: У8 | H12: =Настройки!$B$14 -> Сборка | J12: У9 | K12: =Настройки!$B$15 -> Электромонтаж | M12: У10 | N12: =Настройки!$B$16 -> ОТК и склад ГП

Sheet У1 Заказы
A1: =UPPER(Настройки!$B$7)&" — ФОРМА ЗАКАЗОВ (30 шт). Названия операций редактируются в шапке" -> КОНСТРУКТОРСКОЕ БЮРО — ФОРМА ЗАКАЗОВ (30 шт). Названия операций редактируются в шапке
A2: № заказа | B2: Изделие | C2: Схемы | F2: Компоновка | I2: Деталировка | L2: Спецификация | O2: Согласование | R2: Оп.6 | U2: Оп.7 | X2: Оп.8
C3: Старт | D3: Смен | E3: Факт | F3: Старт | G3: Смен | H3: Факт | I3: Старт | J3: Смен | K3: Факт | L3: Старт | M3: Смен | N3: Факт | O3: Старт | P3: Смен | Q3: Факт | R3: Старт | S3: Смен | T3: Факт | U3: Старт | V3: Смен | W3: Факт | X3: Старт | Y3: Смен | Z3: Факт
A4: =IF('Реестр заказов'!B4="","",'Реестр заказов'!B4) -> 26-1817 | B4: =IF('Реестр заказов'!C4="","",'Реестр заказов'!C4) -> Шкаф РУНН | C4: =DATE(2026,7,1) -> 46204 | D4: 1 | E4: =DATE(2026,7,2) -> 46205 | I4: =DATE(2026,7,2) -> 46205 | J4: 2 | K4: =DATE(2026,7,3) -> 46206
A5: =IF('Реестр заказов'!B5="","",'Реестр заказов'!B5) -> 26-1455 | B5: =IF('Реестр заказов'!C5="","",'Реестр заказов'!C5) -> КТП-1000 | C5: =DATE(2026,7,2) -> 46205 | D5: 1 | E5: =DATE(2026,7,3) -> 46206 | I5: =DATE(2026,7,3) -> 46206 | J5: 2 | K5: =DATE(2026,7,7) -> 46210
A6: =IF('Реестр заказов'!B6="","",'Реестр заказов'!B6) -> 26-1905 | B6: =IF('Реестр заказов'!C6="","",'Реестр заказов'!C6) -> ЩО-70 | C6: =DATE(2026,7,6) -> 46209 | D6: 2 | E6: =DATE(2026,7,8) -> 46211 | I6: =DATE(2026,7,8) -> 46211 | J6: 3
A7: =IF('Реестр заказов'!B7="","",'Реестр заказов'!B7) | B7: =IF('Реестр заказов'!C7="","",'Реестр заказов'!C7)
A8: =IF('Реестр заказов'!B8="","",'Реестр заказов'!B8) | B8: =IF('Реестр заказов'!C8="","",'Реестр заказов'!C8)
A9: =IF('Реестр заказов'!B9="","",'Реестр заказов'!B9) | B9: =IF('Реестр заказов'!C9="","",'Реестр заказов'!C9)
A10: =IF('Реестр заказов'!B10="","",'Реестр заказов'!B10) | B10: =IF('Реестр заказов'!C10="","",'Реестр заказов'!C10)
A11: =IF('Реестр заказов'!B11="","",'Реестр заказов'!B11) | B11: =IF('Реестр заказов'!C11="","",'Реестр заказов'!C11)
A12: =IF('Реестр заказов'!B12="","",'Реестр заказов'!B12) | B12: =IF('Реестр заказов'!C12="","",'Реестр заказов'!C12)
A13: =IF('Реестр заказов'!B13="","",'Реестр заказов'!B13) | B13: =IF('Реестр заказов'!C13="","",'Реестр заказов'!C13)
A14: =IF('Реестр заказов'!B14="","",'Реестр заказов'!B14) | B14: =IF('Реестр заказов'!C14="","",'Реестр заказов'!C14)
A15: =IF('Реестр заказов'!B15="","",'Реестр заказов'!B15) | B15: =IF('Реестр заказов'!C15="","",'Реестр заказов'!C15)
A16: =IF('Реестр заказов'!B16="","",'Реестр заказов'!B16) | B16: =IF('Реестр заказов'!C16="","",'Реестр заказов'!C16)
A17: =IF('Реестр заказов'!B17="","",'Реестр заказов'!B17) | B17: =IF('Реестр заказов'!C17="","",'Реестр заказов'!C17)
A18: =IF('Реестр заказов'!B18="","",'Реестр заказов'!B18) | B18: =IF('Реестр заказов'!C18="","",'Реестр заказов'!C18)
... A33: =IF('Реестр заказов'!B33="","",'Реестр заказов'!B33) | B33: =IF('Реестр заказов'!C33="","",'Реестр заказов'!C33)

Sheet У1 Ввод
A1: =UPPER(Настройки!$B$7)&" — ВВОД ДАННЫХ (заполняется автоматически из формы заказов)" -> КОНСТРУКТОРСКОЕ БЮРО — ВВОД ДАННЫХ (заполняется автоматически из формы заказов)
A3: Участок: | B3: =Настройки!$B$7 -> Конструкторское бюро | E3: Месяц: | F3: =CHOOSE(MONTH(StartDate),"Январь","Февраль","Март","Апрель","Май","Июнь","Июль","Август","Сентябрь","Октябрь","Ноябрь","Декабрь")&" "&YEAR(StartDate) -> Июль 2026
A4: Бригад в смену (100%): | C4: =Настройки!$E$7 -> 4
A11: № | B11: Номер заказа | C11: Наименование операции | D11: План: дата старта | E11: Продолж-ть, смен | F11: План: дата завершения (учёт вых.) | G11: Факт: дата завершения | J11: Проверка дня старта | K11: Статус
A12: 1 | B12: ='У1 Заказы'!$A$4 -> 26-1817 | C12: =IF($B12="","",'У1 Заказы'!$C$2) -> Схемы | D12: =IF('У1 Заказы'!C4="","",'У1 Заказы'!C4) -> 46204 | E12: =IF('У1 Заказы'!D4="","",'У1 Заказы'!D4) -> 1 | F12: =IF(OR(D12="",E12="",E12=0),"",WORKDAY(D12,MAX(0,CEILING(E12,1)-1))) -> 46204 | G12: =IF('У1 Заказы'!E4="","",'У1 Заказы'!E4) -> 46205 | J12: =IF(D12="","",IF(WEEKDAY(D12,2)>5,"⚠ Выходной","Рабочий день")) -> Рабочий день | K12: =IF(OR($B12="",D12=""),"",IF(G12<>"","✔ Выполнен","В работе")) -> ✔ Выполнен
A13: 2 | B13: ='У1 Заказы'!$A$4 -> 26-1817 | C13: =IF($B13="","",'У1 Заказы'!$F$2) -> Компоновка | D13: =IF('У1 Заказы'!F4="","",'У1 Заказы'!F4) | E13: =IF('У1 Заказы'!G4="","",'У1 Заказы'!G4) | F13: =IF(OR(D13="",E13="",E13=0),"",WORKDAY(D13,MAX(0,CEILING(E13,1)-1))) | G13: =IF('У1 Заказы'!H4="","",'У1 Заказы'!H4) | J13: =IF(D13="","",IF(WEEKDAY(D13,2)>5,"⚠ Выходной","Рабочий день")) | K13: =IF(OR($B13="",D13=""),"",IF(G13<>"","✔ Выполнен","В работе"))
A14: 3 | B14: ='У1 Заказы'!$A$4 -> 26-1817 | C14: =IF($B14="","",'У1 Заказы'!$I$2) -> Деталировка | D14: =IF('У1 Заказы'!I4="","",'У1 Заказы'!I4) -> 46205 | E14: =IF('У1 Заказы'!J4="","",'У1 Заказы'!J4) -> 2 | F14: =IF(OR(D14="",E14="",E14=0),"",WORKDAY(D14,MAX(0,CEILING(E14,1)-1))) -> 46206 | G14: =IF('У1 Заказы'!K4="","",'У1 Заказы'!K4) -> 46206 | J14: =IF(D14="","",IF(WEEKDAY(D14,2)>5,"⚠ Выходной","Рабочий день")) -> Рабочий день | K14: =IF(OR($B14="",D14=""),"",IF(G14<>"","✔ Выполнен","В работе")) -> ✔ Выполнен
A15: 4 | B15: ='У1 Заказы'!$A$4 -> 26-1817 | C15: =IF($B15="","",'У1 Заказы'!$L$2) -> Спецификация | D15: =IF('У1 Заказы'!L4="","",'У1 Заказы'!L4) | E15: =IF('У1 Заказы'!M4="","",'У1 Заказы'!M4) | F15: =IF(OR(D15="",E15="",E15=0),"",WORKDAY(D15,MAX(0,CEILING(E15,1)-1))) | G15: =IF('У1 Заказы'!N4="","",'У1 Заказы'!N4) | J15: =IF(D15="","",IF(WEEKDAY(D15,2)>5,"⚠ Выходной","Рабочий день")) | K15: =IF(OR($B15="",D15=""),"",IF(G15<>"","✔ Выполнен","В работе"))
A16: 5 | B16: ='У1 Заказы'!$A$4 -> 26-1817 | C16: =IF($B16="","",'У1 Заказы'!$O$2) -> Согласование | D16: =IF('У1 Заказы'!O4="","",'У1 Заказы'!O4) | E16: =IF('У1 Заказы'!P4="","",'У1 Заказы'!P4) | F16: =IF(OR(D16="",E16="",E16=0),"",WORKDAY(D16,MAX(0,CEILING(E16,1)-1))) | G16: =IF('У1 Заказы'!Q4="","",'У1 Заказы'!Q4) | J16: =IF(D16="","",IF(WEEKDAY(D16,2)>5,"⚠ Выходной","Рабочий день")) | K16: =IF(OR($B16="",D16=""),"",IF(G16<>"","✔ Выполнен","В работе"))
A17: 6 | B17: ='У1 Заказы'!$A$4 -> 26-1817 | C17: =IF($B17="","",'У1 Заказы'!$R$2) -> Оп.6 | D17: =IF('У1 Заказы'!R4="","",'У1 Заказы'!R4) | E17: =IF('У1 Заказы'!S4="","",'У1 Заказы'!S4) | F17: =IF(OR(D17="",E17="",E17=0),"",WORKDAY(D17,MAX(0,CEILING(E17,1)-1))) | G17: =IF('У1 Заказы'!T4="","",'У1 Заказы'!T4) | J17: =IF(D17="","",IF(WEEKDAY(D17,2)>5,"⚠ Выходной","Рабочий день")) | K17: =IF(OR($B17="",D17=""),"",IF(G17<>"","✔ Выполнен","В работе"))
A18: 7 | B18: ='У1 Заказы'!$A$4 -> 26-1817 | C18: =IF($B18="","",'У1 Заказы'!$U$2) -> Оп.7 | D18: =IF('У1 Заказы'!U4="","",'У1 Заказы'!U4) | E18: =IF('У1 Заказы'!V4="","",'У1 Заказы'!V4) | F18: =IF(OR(D18="",E18="",E18=0),"",WORKDAY(D18,MAX(0,CEILING(E18,1)-1))) | G18: =IF('У1 Заказы'!W4="","",'У1 Заказы'!W4) | J18: =IF(D18="","",IF(WEEKDAY(D18,2)>5,"⚠ Выходной","Рабочий день")) | K18: =IF(OR($B18="",D18=""),"",IF(G18<>"","✔ Выполнен","В работе"))
A19: 8 | B19: ='У1 Заказы'!$A$4 -> 26-1817 | C19: =IF($B19="","",'У1 Заказы'!$X$2) -> Оп.8 | D19: =IF('У1 Заказы'!X4="","",'У1 Заказы'!X4) | E19: =IF('У1 Заказы'!Y4="","",'У1 Заказы'!Y4) | F19: =IF(OR(D19="",E19="",E19=0),"",WORKDAY(D19,MAX(0,CEILING(E19,1)-1))) | G19: =IF('У1 Заказы'!Z4="","",'У1 Заказы'!Z4) | J19: =IF(D19="","",IF(WEEKDAY(D19,2)>5,"⚠ Выходной","Рабочий день")) | K19: =IF(OR($B19="",D19=""),"",IF(G19<>"","✔ Выполнен","В работе"))
A20: 9 | B20: ='У1 Заказы'!$A$5 -> 26-1455 | C20: =IF($B20="","",'У1 Заказы'!$C$2) -> Схемы | D20: =IF('У1 Заказы'!C5="","",'У1 Заказы'!C5) -> 46205 | E20: =IF('У1 Заказы'!D5="","",'У1 Заказы'!D5) -> 1 | F20: =IF(OR(D20="",E20="",E20=0),"",WORKDAY(D20,MAX(0,CEILING(E20,1)-1))) -> 46205 | G20: =IF('У1 Заказы'!E5="","",'У1 Заказы'!E5) -> 46206 | J20: =IF(D20="","",IF(WEEKDAY(D20,2)>5,"⚠ Выходной","Рабочий день")) -> Рабочий день | K20: =IF(OR($B20="",D20=""),"",IF(G20<>"","✔ Выполнен","В работе")) -> ✔ Выполнен
